Execution of job "run.<locals>.<lambda> (trigger: cron[minute='0-59', second='1'], next run at: 2017-11-03 14:04:01 +08)" skipped: maximum number of running instances reached (1)
Job "run.<locals>.<lambda> (trigger: cron[minute='0-59', second='1'], next run at: 2017-11-12 16:41:01 +08)" raised an exception
Traceback (most recent call last):
  File "/Library/Frameworks/Python.framework/Versions/3.6/lib/python3.6/site-packages/apscheduler/executors/base.py", line 125, in run_job
    retval = job.func(*job.args, **job.kwargs)
  File "/Users/tianyangzhao/PycharmProjects/universal_ems/local_ems.py", line 89, in <lambda>
    session_short_term_operation),
  File "/Users/tianyangzhao/PycharmProjects/universal_ems/economic_dispatch/main.py", line 124, in middle_term_operation_lems
    dynamic_model = information_formulation_extraction_dynamic.info_formulation(local_models, Target_time)
  File "/Users/tianyangzhao/PycharmProjects/universal_ems/data_management/information_management.py", line 161, in info_formulation
    Type = args[2]
IndexError: tuple index out of range
Execution of job "middle_term_operation.middle_term_operation_uems (trigger: cron[minute='0-59', second='1'], next run at: 2017-11-12 16:41:01 +08)" skipped: maximum number of running instances reached (1)
Job "run.<locals>.<lambda> (trigger: cron[minute='0-59', second='1'], next run at: 2017-11-12 16:42:01 +08)" raised an exception
Traceback (most recent call last):
  File "/Library/Frameworks/Python.framework/Versions/3.6/lib/python3.6/site-packages/apscheduler/executors/base.py", line 125, in run_job
    retval = job.func(*job.args, **job.kwargs)
  File "/Users/tianyangzhao/PycharmProjects/universal_ems/local_ems.py", line 89, in <lambda>
    session_short_term_operation),
  File "/Users/tianyangzhao/PycharmProjects/universal_ems/economic_dispatch/main.py", line 124, in middle_term_operation_lems
    dynamic_model = information_formulation_extraction_dynamic.info_formulation(local_models, Target_time)
  File "/Users/tianyangzhao/PycharmProjects/universal_ems/data_management/information_management.py", line 161, in info_formulation
    Type = args[2]
IndexError: tuple index out of range
Job "run.<locals>.<lambda> (trigger: cron[minute='0-59', second='*/10'], next run at: 2017-11-12 16:56:00 +08)" raised an exception
Traceback (most recent call last):
  File "/Library/Frameworks/Python.framework/Versions/3.6/lib/python3.6/site-packages/apscheduler/executors/base.py", line 125, in run_job
    retval = job.func(*job.args, **job.kwargs)
  File "/Users/tianyangzhao/PycharmProjects/universal_ems/local_ems.py", line 89, in <lambda>
    session_short_term_operation),
  File "/Users/tianyangzhao/PycharmProjects/universal_ems/economic_dispatch/main.py", line 124, in middle_term_operation_lems
    dynamic_model = information_formulation_extraction_dynamic.info_formulation(local_models, Target_time)
  File "/Users/tianyangzhao/PycharmProjects/universal_ems/data_management/information_management.py", line 161, in info_formulation
    Type = args[2]
IndexError: tuple index out of range
Execution of job "run.<locals>.<lambda> (trigger: cron[minute='0-59', second='*/10'], next run at: 2017-11-12 17:02:30 +08)" skipped: maximum number of running instances reached (1)
Execution of job "middle_term_operation.middle_term_operation_uems (trigger: cron[minute='0-59', second='*/10'], next run at: 2017-11-12 17:02:30 +08)" skipped: maximum number of running instances reached (1)
Execution of job "middle_term_operation.middle_term_operation_uems (trigger: cron[minute='0-59', second='*/10'], next run at: 2017-11-12 17:02:40 +08)" skipped: maximum number of running instances reached (1)
Execution of job "run.<locals>.<lambda> (trigger: cron[minute='0-59', second='*/10'], next run at: 2017-11-12 17:02:40 +08)" skipped: maximum number of running instances reached (1)
Execution of job "run.<locals>.<lambda> (trigger: cron[minute='0-59', second='*/10'], next run at: 2017-11-12 17:02:50 +08)" skipped: maximum number of running instances reached (1)
Execution of job "middle_term_operation.middle_term_operation_uems (trigger: cron[minute='0-59', second='*/10'], next run at: 2017-11-12 17:02:50 +08)" skipped: maximum number of running instances reached (1)
Execution of job "run.<locals>.<lambda> (trigger: cron[minute='0-59', second='*/10'], next run at: 2017-11-12 17:03:00 +08)" skipped: maximum number of running instances reached (1)
Execution of job "middle_term_operation.middle_term_operation_uems (trigger: cron[minute='0-59', second='*/10'], next run at: 2017-11-12 17:03:00 +08)" skipped: maximum number of running instances reached (1)
Execution of job "middle_term_operation.middle_term_operation_uems (trigger: cron[minute='0-59', second='*/10'], next run at: 2017-11-12 17:03:10 +08)" skipped: maximum number of running instances reached (1)
Execution of job "run.<locals>.<lambda> (trigger: cron[minute='0-59', second='*/10'], next run at: 2017-11-12 17:03:10 +08)" skipped: maximum number of running instances reached (1)
Execution of job "middle_term_operation.middle_term_operation_uems (trigger: cron[minute='0-59', second='*/10'], next run at: 2017-11-12 17:03:20 +08)" skipped: maximum number of running instances reached (1)
Execution of job "run.<locals>.<lambda> (trigger: cron[minute='0-59', second='*/10'], next run at: 2017-11-12 17:03:20 +08)" skipped: maximum number of running instances reached (1)
Execution of job "run.<locals>.<lambda> (trigger: cron[minute='0-59', second='*/10'], next run at: 2017-11-12 17:03:30 +08)" skipped: maximum number of running instances reached (1)
Execution of job "middle_term_operation.middle_term_operation_uems (trigger: cron[minute='0-59', second='*/10'], next run at: 2017-11-12 17:03:30 +08)" skipped: maximum number of running instances reached (1)
Execution of job "run.<locals>.<lambda> (trigger: cron[minute='0-59', second='*/10'], next run at: 2017-11-12 17:03:40 +08)" skipped: maximum number of running instances reached (1)
Execution of job "middle_term_operation.middle_term_operation_uems (trigger: cron[minute='0-59', second='*/10'], next run at: 2017-11-12 17:03:40 +08)" skipped: maximum number of running instances reached (1)
Execution of job "run.<locals>.<lambda> (trigger: cron[minute='0-59', second='*/10'], next run at: 2017-11-12 17:03:50 +08)" skipped: maximum number of running instances reached (1)
Execution of job "middle_term_operation.middle_term_operation_uems (trigger: cron[minute='0-59', second='*/10'], next run at: 2017-11-12 17:03:50 +08)" skipped: maximum number of running instances reached (1)
Execution of job "middle_term_operation.middle_term_operation_uems (trigger: cron[minute='0-59', second='*/10'], next run at: 2017-11-12 17:04:00 +08)" skipped: maximum number of running instances reached (1)
Execution of job "run.<locals>.<lambda> (trigger: cron[minute='0-59', second='*/10'], next run at: 2017-11-12 17:04:00 +08)" skipped: maximum number of running instances reached (1)
Execution of job "run.<locals>.<lambda> (trigger: cron[minute='0-59', second='*/10'], next run at: 2017-11-12 17:04:10 +08)" skipped: maximum number of running instances reached (1)
Execution of job "middle_term_operation.middle_term_operation_uems (trigger: cron[minute='0-59', second='*/10'], next run at: 2017-11-12 17:04:10 +08)" skipped: maximum number of running instances reached (1)
Execution of job "middle_term_operation.middle_term_operation_uems (trigger: cron[minute='0-59', second='*/10'], next run at: 2017-11-12 17:04:20 +08)" skipped: maximum number of running instances reached (1)
Execution of job "run.<locals>.<lambda> (trigger: cron[minute='0-59', second='*/10'], next run at: 2017-11-12 17:04:20 +08)" skipped: maximum number of running instances reached (1)
Execution of job "middle_term_operation.middle_term_operation_uems (trigger: cron[minute='0-59', second='*/10'], next run at: 2017-11-12 17:04:30 +08)" skipped: maximum number of running instances reached (1)
Execution of job "run.<locals>.<lambda> (trigger: cron[minute='0-59', second='*/10'], next run at: 2017-11-12 17:04:30 +08)" skipped: maximum number of running instances reached (1)
Execution of job "run.<locals>.<lambda> (trigger: cron[minute='0-59', second='*/10'], next run at: 2017-11-12 17:04:40 +08)" skipped: maximum number of running instances reached (1)
Execution of job "middle_term_operation.middle_term_operation_uems (trigger: cron[minute='0-59', second='*/10'], next run at: 2017-11-12 17:04:40 +08)" skipped: maximum number of running instances reached (1)
Execution of job "middle_term_operation.middle_term_operation_uems (trigger: cron[minute='0-59', second='*/10'], next run at: 2017-11-12 17:04:50 +08)" skipped: maximum number of running instances reached (1)
Execution of job "run.<locals>.<lambda> (trigger: cron[minute='0-59', second='*/10'], next run at: 2017-11-12 17:04:50 +08)" skipped: maximum number of running instances reached (1)
Execution of job "run.<locals>.<lambda> (trigger: cron[minute='0-59', second='*/10'], next run at: 2017-11-12 17:05:00 +08)" skipped: maximum number of running instances reached (1)
Execution of job "middle_term_operation.middle_term_operation_uems (trigger: cron[minute='0-59', second='*/10'], next run at: 2017-11-12 17:05:00 +08)" skipped: maximum number of running instances reached (1)
Execution of job "middle_term_operation.middle_term_operation_uems (trigger: cron[minute='0-59', second='*/10'], next run at: 2017-11-12 17:06:30 +08)" skipped: maximum number of running instances reached (1)
Execution of job "run.<locals>.<lambda> (trigger: cron[minute='0-59', second='*/10'], next run at: 2017-11-12 17:06:30 +08)" skipped: maximum number of running instances reached (1)
Execution of job "middle_term_operation.middle_term_operation_uems (trigger: cron[minute='0-59', second='*/10'], next run at: 2017-11-12 17:06:40 +08)" skipped: maximum number of running instances reached (1)
Execution of job "run.<locals>.<lambda> (trigger: cron[minute='0-59', second='*/10'], next run at: 2017-11-12 17:06:40 +08)" skipped: maximum number of running instances reached (1)
Execution of job "middle_term_operation.middle_term_operation_uems (trigger: cron[minute='0-59', second='*/10'], next run at: 2017-11-12 17:06:50 +08)" skipped: maximum number of running instances reached (1)
Execution of job "run.<locals>.<lambda> (trigger: cron[minute='0-59', second='*/10'], next run at: 2017-11-12 17:06:50 +08)" skipped: maximum number of running instances reached (1)
Execution of job "run.<locals>.<lambda> (trigger: cron[minute='0-59', second='*/10'], next run at: 2017-11-12 17:07:00 +08)" skipped: maximum number of running instances reached (1)
Execution of job "middle_term_operation.middle_term_operation_uems (trigger: cron[minute='0-59', second='*/10'], next run at: 2017-11-12 17:07:00 +08)" skipped: maximum number of running instances reached (1)
Job "run.<locals>.<lambda> (trigger: cron[minute='0-59', second='*/10'], next run at: 2017-11-12 18:11:10 +08)" raised an exception
Traceback (most recent call last):
  File "/Library/Frameworks/Python.framework/Versions/3.6/lib/python3.6/site-packages/apscheduler/executors/base.py", line 125, in run_job
    retval = job.func(*job.args, **job.kwargs)
  File "/Users/tianyangzhao/PycharmProjects/universal_ems/local_ems.py", line 89, in <lambda>
    session_short_term_operation),
  File "/Users/tianyangzhao/PycharmProjects/universal_ems/economic_dispatch/main.py", line 124, in middle_term_operation_lems
    dynamic_model = information_formulation_extraction_dynamic.info_formulation(local_models, Target_time)
  File "/Users/tianyangzhao/PycharmProjects/universal_ems/data_management/information_management.py", line 161, in info_formulation
    Type = args[2]
IndexError: tuple index out of range
Execution of job "middle_term_operation.middle_term_operation_uems (trigger: cron[minute='0-59', second='*/10'], next run at: 2017-11-12 18:11:10 +08)" skipped: maximum number of running instances reached (1)
Job "run.<locals>.<lambda> (trigger: cron[minute='0-59', second='*/10'], next run at: 2017-11-12 18:11:20 +08)" raised an exception
Traceback (most recent call last):
  File "/Library/Frameworks/Python.framework/Versions/3.6/lib/python3.6/site-packages/apscheduler/executors/base.py", line 125, in run_job
    retval = job.func(*job.args, **job.kwargs)
  File "/Users/tianyangzhao/PycharmProjects/universal_ems/local_ems.py", line 89, in <lambda>
    session_short_term_operation),
  File "/Users/tianyangzhao/PycharmProjects/universal_ems/economic_dispatch/main.py", line 124, in middle_term_operation_lems
    dynamic_model = information_formulation_extraction_dynamic.info_formulation(local_models, Target_time)
  File "/Users/tianyangzhao/PycharmProjects/universal_ems/data_management/information_management.py", line 161, in info_formulation
    Type = args[2]
IndexError: tuple index out of range
Execution of job "middle_term_operation.middle_term_operation_uems (trigger: cron[minute='0-59', second='*/10'], next run at: 2017-11-12 18:11:20 +08)" skipped: maximum number of running instances reached (1)
Job "run.<locals>.<lambda> (trigger: cron[minute='0-59', second='*/10'], next run at: 2017-11-12 18:11:30 +08)" raised an exception
Traceback (most recent call last):
  File "/Library/Frameworks/Python.framework/Versions/3.6/lib/python3.6/site-packages/apscheduler/executors/base.py", line 125, in run_job
    retval = job.func(*job.args, **job.kwargs)
  File "/Users/tianyangzhao/PycharmProjects/universal_ems/local_ems.py", line 89, in <lambda>
    session_short_term_operation),
  File "/Users/tianyangzhao/PycharmProjects/universal_ems/economic_dispatch/main.py", line 124, in middle_term_operation_lems
    dynamic_model = information_formulation_extraction_dynamic.info_formulation(local_models, Target_time)
  File "/Users/tianyangzhao/PycharmProjects/universal_ems/data_management/information_management.py", line 161, in info_formulation
    Type = args[2]
IndexError: tuple index out of range
Job "run.<locals>.<lambda> (trigger: cron[minute='0-59', second='*/10'], next run at: 2017-11-12 18:18:50 +08)" raised an exception
Traceback (most recent call last):
  File "/Library/Frameworks/Python.framework/Versions/3.6/lib/python3.6/site-packages/apscheduler/executors/base.py", line 125, in run_job
    retval = job.func(*job.args, **job.kwargs)
  File "/Users/tianyangzhao/PycharmProjects/universal_ems/local_ems.py", line 89, in <lambda>
    session_short_term_operation),
  File "/Users/tianyangzhao/PycharmProjects/universal_ems/economic_dispatch/main.py", line 124, in middle_term_operation_lems
    dynamic_model = information_formulation_extraction_dynamic.info_formulation(local_models, Target_time)
  File "/Users/tianyangzhao/PycharmProjects/universal_ems/data_management/information_management.py", line 161, in info_formulation
    Type = args[2]
IndexError: tuple index out of range
Job "run.<locals>.<lambda> (trigger: cron[minute='0-59', second='*/10'], next run at: 2017-11-12 18:19:00 +08)" raised an exception
Traceback (most recent call last):
  File "/Library/Frameworks/Python.framework/Versions/3.6/lib/python3.6/site-packages/apscheduler/executors/base.py", line 125, in run_job
    retval = job.func(*job.args, **job.kwargs)
  File "/Users/tianyangzhao/PycharmProjects/universal_ems/local_ems.py", line 89, in <lambda>
    session_short_term_operation),
  File "/Users/tianyangzhao/PycharmProjects/universal_ems/economic_dispatch/main.py", line 124, in middle_term_operation_lems
    dynamic_model = information_formulation_extraction_dynamic.info_formulation(local_models, Target_time)
  File "/Users/tianyangzhao/PycharmProjects/universal_ems/data_management/information_management.py", line 161, in info_formulation
    Type = args[2]
IndexError: tuple index out of range
Job "run.<locals>.<lambda> (trigger: cron[minute='0-59', second='*/10'], next run at: 2017-11-12 18:19:10 +08)" raised an exception
Traceback (most recent call last):
  File "/Library/Frameworks/Python.framework/Versions/3.6/lib/python3.6/site-packages/apscheduler/executors/base.py", line 125, in run_job
    retval = job.func(*job.args, **job.kwargs)
  File "/Users/tianyangzhao/PycharmProjects/universal_ems/local_ems.py", line 89, in <lambda>
    session_short_term_operation),
  File "/Users/tianyangzhao/PycharmProjects/universal_ems/economic_dispatch/main.py", line 124, in middle_term_operation_lems
    dynamic_model = information_formulation_extraction_dynamic.info_formulation(local_models, Target_time)
  File "/Users/tianyangzhao/PycharmProjects/universal_ems/data_management/information_management.py", line 161, in info_formulation
    Type = args[2]
IndexError: tuple index out of range
Job "run.<locals>.<lambda> (trigger: cron[minute='0-59', second='*/10'], next run at: 2017-11-12 18:19:30 +08)" raised an exception
Traceback (most recent call last):
  File "/Library/Frameworks/Python.framework/Versions/3.6/lib/python3.6/site-packages/apscheduler/executors/base.py", line 125, in run_job
    retval = job.func(*job.args, **job.kwargs)
  File "/Users/tianyangzhao/PycharmProjects/universal_ems/local_ems.py", line 89, in <lambda>
    session_short_term_operation),
  File "/Users/tianyangzhao/PycharmProjects/universal_ems/economic_dispatch/main.py", line 124, in middle_term_operation_lems
    dynamic_model = information_formulation_extraction_dynamic.info_formulation(local_models, Target_time)
  File "/Users/tianyangzhao/PycharmProjects/universal_ems/data_management/information_management.py", line 161, in info_formulation
    Type = args[2]
IndexError: tuple index out of range
Execution of job "middle_term_operation.middle_term_operation_uems (trigger: cron[minute='0-59', second='*/10'], next run at: 2017-11-12 18:19:30 +08)" skipped: maximum number of running instances reached (1)
Job "run.<locals>.<lambda> (trigger: cron[minute='0-59', second='*/10'], next run at: 2017-11-12 18:19:40 +08)" raised an exception
Traceback (most recent call last):
  File "/Library/Frameworks/Python.framework/Versions/3.6/lib/python3.6/site-packages/apscheduler/executors/base.py", line 125, in run_job
    retval = job.func(*job.args, **job.kwargs)
  File "/Users/tianyangzhao/PycharmProjects/universal_ems/local_ems.py", line 89, in <lambda>
    session_short_term_operation),
  File "/Users/tianyangzhao/PycharmProjects/universal_ems/economic_dispatch/main.py", line 124, in middle_term_operation_lems
    dynamic_model = information_formulation_extraction_dynamic.info_formulation(local_models, Target_time)
  File "/Users/tianyangzhao/PycharmProjects/universal_ems/data_management/information_management.py", line 161, in info_formulation
    Type = args[2]
IndexError: tuple index out of range
Execution of job "middle_term_operation.middle_term_operation_uems (trigger: cron[minute='0-59', second='*/10'], next run at: 2017-11-12 18:19:40 +08)" skipped: maximum number of running instances reached (1)
Job "run.<locals>.<lambda> (trigger: cron[minute='0-59', second='*/10'], next run at: 2017-11-12 18:19:50 +08)" raised an exception
Traceback (most recent call last):
  File "/Library/Frameworks/Python.framework/Versions/3.6/lib/python3.6/site-packages/apscheduler/executors/base.py", line 125, in run_job
    retval = job.func(*job.args, **job.kwargs)
  File "/Users/tianyangzhao/PycharmProjects/universal_ems/local_ems.py", line 89, in <lambda>
    session_short_term_operation),
  File "/Users/tianyangzhao/PycharmProjects/universal_ems/economic_dispatch/main.py", line 124, in middle_term_operation_lems
    dynamic_model = information_formulation_extraction_dynamic.info_formulation(local_models, Target_time)
  File "/Users/tianyangzhao/PycharmProjects/universal_ems/data_management/information_management.py", line 161, in info_formulation
    Type = args[2]
IndexError: tuple index out of range
Execution of job "middle_term_operation.middle_term_operation_uems (trigger: cron[minute='0-59', second='*/10'], next run at: 2017-11-12 18:19:50 +08)" skipped: maximum number of running instances reached (1)
Job "run.<locals>.<lambda> (trigger: cron[minute='0-59', second='*/10'], next run at: 2017-11-12 18:20:00 +08)" raised an exception
Traceback (most recent call last):
  File "/Library/Frameworks/Python.framework/Versions/3.6/lib/python3.6/site-packages/apscheduler/executors/base.py", line 125, in run_job
    retval = job.func(*job.args, **job.kwargs)
  File "/Users/tianyangzhao/PycharmProjects/universal_ems/local_ems.py", line 89, in <lambda>
    session_short_term_operation),
  File "/Users/tianyangzhao/PycharmProjects/universal_ems/economic_dispatch/main.py", line 124, in middle_term_operation_lems
    dynamic_model = information_formulation_extraction_dynamic.info_formulation(local_models, Target_time)
  File "/Users/tianyangzhao/PycharmProjects/universal_ems/data_management/information_management.py", line 161, in info_formulation
    Type = args[2]
IndexError: tuple index out of range
Execution of job "middle_term_operation.middle_term_operation_uems (trigger: cron[minute='0-59', second='*/10'], next run at: 2017-11-12 18:20:00 +08)" skipped: maximum number of running instances reached (1)
Job "run.<locals>.<lambda> (trigger: cron[minute='0-59', second='*/10'], next run at: 2017-11-12 18:20:10 +08)" raised an exception
Traceback (most recent call last):
  File "/Library/Frameworks/Python.framework/Versions/3.6/lib/python3.6/site-packages/apscheduler/executors/base.py", line 125, in run_job
    retval = job.func(*job.args, **job.kwargs)
  File "/Users/tianyangzhao/PycharmProjects/universal_ems/local_ems.py", line 89, in <lambda>
    session_short_term_operation),
  File "/Users/tianyangzhao/PycharmProjects/universal_ems/economic_dispatch/main.py", line 124, in middle_term_operation_lems
    dynamic_model = information_formulation_extraction_dynamic.info_formulation(local_models, Target_time)
  File "/Users/tianyangzhao/PycharmProjects/universal_ems/data_management/information_management.py", line 161, in info_formulation
    Type = args[2]
IndexError: tuple index out of range
Job "run.<locals>.<lambda> (trigger: cron[minute='0-59', second='*/10'], next run at: 2017-11-12 18:51:50 +08)" raised an exception
Traceback (most recent call last):
  File "/Library/Frameworks/Python.framework/Versions/3.6/lib/python3.6/site-packages/apscheduler/executors/base.py", line 125, in run_job
    retval = job.func(*job.args, **job.kwargs)
  File "/Users/tianyangzhao/PycharmProjects/universal_ems/local_ems.py", line 89, in <lambda>
    session_short_term_operation),
  File "/Users/tianyangzhao/PycharmProjects/universal_ems/economic_dispatch/main.py", line 124, in middle_term_operation_lems
    dynamic_model = information_formulation_extraction_dynamic.info_formulation(local_models, Target_time)
  File "/Users/tianyangzhao/PycharmProjects/universal_ems/data_management/information_management.py", line 161, in info_formulation
    Type = args[2]
IndexError: tuple index out of range
Execution of job "middle_term_operation.middle_term_operation_uems (trigger: cron[minute='0-59', second='*/10'], next run at: 2017-11-12 18:51:50 +08)" skipped: maximum number of running instances reached (1)
Job "run.<locals>.<lambda> (trigger: cron[minute='0-59', second='*/10'], next run at: 2017-11-12 18:52:00 +08)" raised an exception
Traceback (most recent call last):
  File "/Library/Frameworks/Python.framework/Versions/3.6/lib/python3.6/site-packages/apscheduler/executors/base.py", line 125, in run_job
    retval = job.func(*job.args, **job.kwargs)
  File "/Users/tianyangzhao/PycharmProjects/universal_ems/local_ems.py", line 89, in <lambda>
    session_short_term_operation),
  File "/Users/tianyangzhao/PycharmProjects/universal_ems/economic_dispatch/main.py", line 124, in middle_term_operation_lems
    dynamic_model = information_formulation_extraction_dynamic.info_formulation(local_models, Target_time)
  File "/Users/tianyangzhao/PycharmProjects/universal_ems/data_management/information_management.py", line 161, in info_formulation
    Type = args[2]
IndexError: tuple index out of range
Job "run.<locals>.<lambda> (trigger: cron[minute='0-59', second='1'], next run at: 2017-11-12 19:33:01 +08)" raised an exception
Traceback (most recent call last):
  File "/Library/Frameworks/Python.framework/Versions/3.6/lib/python3.6/site-packages/apscheduler/executors/base.py", line 125, in run_job
    retval = job.func(*job.args, **job.kwargs)
  File "/Users/tianyangzhao/PycharmProjects/universal_ems/local_ems.py", line 89, in <lambda>
    session_short_term_operation),
  File "/Users/tianyangzhao/PycharmProjects/universal_ems/economic_dispatch/main.py", line 124, in middle_term_operation_lems
    dynamic_model = information_formulation_extraction_dynamic.info_formulation(local_models, Target_time)
  File "/Users/tianyangzhao/PycharmProjects/universal_ems/data_management/information_management.py", line 161, in info_formulation
    Type = args[2]
IndexError: tuple index out of range
Execution of job "middle_term_operation.middle_term_operation_uems (trigger: cron[minute='0-59', second='1'], next run at: 2017-11-12 19:35:01 +08)" skipped: maximum number of running instances reached (1)
Execution of job "run.<locals>.<lambda> (trigger: cron[minute='0-59', second='1'], next run at: 2017-11-12 19:35:01 +08)" skipped: maximum number of running instances reached (1)
Job "run.<locals>.<lambda> (trigger: cron[minute='0-59', second='1'], next run at: 2017-11-12 19:36:01 +08)" raised an exception
Traceback (most recent call last):
  File "/Library/Frameworks/Python.framework/Versions/3.6/lib/python3.6/site-packages/apscheduler/executors/base.py", line 125, in run_job
    retval = job.func(*job.args, **job.kwargs)
  File "/Users/tianyangzhao/PycharmProjects/universal_ems/local_ems.py", line 89, in <lambda>
    session_short_term_operation),
  File "/Users/tianyangzhao/PycharmProjects/universal_ems/economic_dispatch/main.py", line 124, in middle_term_operation_lems
    dynamic_model = information_formulation_extraction_dynamic.info_formulation(local_models, Target_time)
  File "/Users/tianyangzhao/PycharmProjects/universal_ems/data_management/information_management.py", line 161, in info_formulation
    Type = args[2]
IndexError: tuple index out of range
Job "run.<locals>.<lambda> (trigger: cron[minute='0-59', second='1'], next run at: 2017-11-12 19:40:01 +08)" raised an exception
Traceback (most recent call last):
  File "/Library/Frameworks/Python.framework/Versions/3.6/lib/python3.6/site-packages/apscheduler/executors/base.py", line 125, in run_job
    retval = job.func(*job.args, **job.kwargs)
  File "/Users/tianyangzhao/PycharmProjects/universal_ems/local_ems.py", line 89, in <lambda>
    session_short_term_operation),
  File "/Users/tianyangzhao/PycharmProjects/universal_ems/economic_dispatch/main.py", line 124, in middle_term_operation_lems
    dynamic_model = information_formulation_extraction_dynamic.info_formulation(local_models, Target_time)
  File "/Users/tianyangzhao/PycharmProjects/universal_ems/data_management/information_management.py", line 161, in info_formulation
    Type = args[2]
IndexError: tuple index out of range
Execution of job "middle_term_operation.middle_term_operation_uems (trigger: cron[minute='0-59', second='1'], next run at: 2017-11-12 19:40:01 +08)" skipped: maximum number of running instances reached (1)
Job "run.<locals>.<lambda> (trigger: cron[minute='0-59', second='1'], next run at: 2017-11-12 19:41:01 +08)" raised an exception
Traceback (most recent call last):
  File "/Library/Frameworks/Python.framework/Versions/3.6/lib/python3.6/site-packages/apscheduler/executors/base.py", line 125, in run_job
    retval = job.func(*job.args, **job.kwargs)
  File "/Users/tianyangzhao/PycharmProjects/universal_ems/local_ems.py", line 89, in <lambda>
    session_short_term_operation),
  File "/Users/tianyangzhao/PycharmProjects/universal_ems/economic_dispatch/main.py", line 124, in middle_term_operation_lems
    dynamic_model = information_formulation_extraction_dynamic.info_formulation(local_models, Target_time)
  File "/Users/tianyangzhao/PycharmProjects/universal_ems/data_management/information_management.py", line 161, in info_formulation
    Type = args[2]
IndexError: tuple index out of range
Job "run.<locals>.<lambda> (trigger: cron[minute='0-59', second='1'], next run at: 2017-11-17 09:16:01 +08)" raised an exception
Traceback (most recent call last):
  File "/Library/Frameworks/Python.framework/Versions/3.6/lib/python3.6/site-packages/apscheduler/executors/base.py", line 125, in run_job
    retval = job.func(*job.args, **job.kwargs)
  File "/Users/tianyangzhao/PycharmProjects/universal_ems/local_ems.py", line 84, in <lambda>
    session_short_term_operation),
  File "/Users/tianyangzhao/PycharmProjects/universal_ems/optimal_power_flow/main.py", line 116, in short_term_operation_lems
    dynamic_model = information_formulation_extraction.info_formulation(local_models, Target_time)
  File "/Users/tianyangzhao/PycharmProjects/universal_ems/data_management/information_management.py", line 54, in info_formulation
    ug_info.PG = model["UG"]["COMMAND_SET_POINT_PG"]
KeyError: 'COMMAND_SET_POINT_PG'
Job "run.<locals>.<lambda> (trigger: cron[minute='0-59', second='1'], next run at: 2017-11-17 09:17:01 +08)" raised an exception
Traceback (most recent call last):
  File "/Library/Frameworks/Python.framework/Versions/3.6/lib/python3.6/site-packages/apscheduler/executors/base.py", line 125, in run_job
    retval = job.func(*job.args, **job.kwargs)
  File "/Users/tianyangzhao/PycharmProjects/universal_ems/local_ems.py", line 84, in <lambda>
    session_short_term_operation),
  File "/Users/tianyangzhao/PycharmProjects/universal_ems/optimal_power_flow/main.py", line 116, in short_term_operation_lems
    dynamic_model = information_formulation_extraction.info_formulation(local_models, Target_time)
  File "/Users/tianyangzhao/PycharmProjects/universal_ems/data_management/information_management.py", line 54, in info_formulation
    ug_info.PG = model["UG"]["COMMAND_SET_POINT_PG"]
KeyError: 'COMMAND_SET_POINT_PG'
Job "run.<locals>.<lambda> (trigger: cron[minute='0-59', second='1'], next run at: 2017-11-17 09:18:01 +08)" raised an exception
Traceback (most recent call last):
  File "/Library/Frameworks/Python.framework/Versions/3.6/lib/python3.6/site-packages/apscheduler/executors/base.py", line 125, in run_job
    retval = job.func(*job.args, **job.kwargs)
  File "/Users/tianyangzhao/PycharmProjects/universal_ems/local_ems.py", line 84, in <lambda>
    session_short_term_operation),
  File "/Users/tianyangzhao/PycharmProjects/universal_ems/optimal_power_flow/main.py", line 116, in short_term_operation_lems
    # Update the dynamic model
  File "/Users/tianyangzhao/PycharmProjects/universal_ems/data_management/information_management.py", line 54, in info_formulation
    ug_info.PG = model["UG"]["COMMAND_SET_POINT_PG"]
KeyError: 'COMMAND_SET_POINT_PG'
Job "run.<locals>.<lambda> (trigger: cron[minute='0-59', second='1'], next run at: 2017-11-17 09:18:01 +08)" raised an exception
Traceback (most recent call last):
  File "/Library/Frameworks/Python.framework/Versions/3.6/lib/python3.6/site-packages/apscheduler/executors/base.py", line 125, in run_job
    retval = job.func(*job.args, **job.kwargs)
  File "/Users/tianyangzhao/PycharmProjects/universal_ems/local_ems.py", line 84, in <lambda>
    session_short_term_operation),
  File "/Users/tianyangzhao/PycharmProjects/universal_ems/optimal_power_flow/main.py", line 117, in short_term_operation_lems
    dynamic_model = information_formulation_extraction.info_formulation(local_models, Target_time)
  File "/Users/tianyangzhao/PycharmProjects/universal_ems/data_management/information_management.py", line 54, in info_formulation
    ug_info.PG = model["UG"]["COMMAND_SET_POINT_PG"]
KeyError: 'COMMAND_SET_POINT_PG'
Job "run.<locals>.<lambda> (trigger: cron[minute='0-59', second='1'], next run at: 2017-11-23 10:01:01 +08)" raised an exception
Traceback (most recent call last):
  File "/Library/Frameworks/Python.framework/Versions/3.6/lib/python3.6/site-packages/sqlalchemy/pool.py", line 1122, in _do_get
    return self._pool.get(wait, self._timeout)
  File "/Library/Frameworks/Python.framework/Versions/3.6/lib/python3.6/site-packages/sqlalchemy/util/queue.py", line 145, in get
    raise Empty
sqlalchemy.util.queue.Empty

During handling of the above exception, another exception occurred:

Traceback (most recent call last):
  File "/Library/Frameworks/Python.framework/Versions/3.6/lib/python3.6/site-packages/sqlalchemy/engine/base.py", line 2147, in _wrap_pool_connect
    return fn()
  File "/Library/Frameworks/Python.framework/Versions/3.6/lib/python3.6/site-packages/sqlalchemy/pool.py", line 387, in connect
    return _ConnectionFairy._checkout(self)
  File "/Library/Frameworks/Python.framework/Versions/3.6/lib/python3.6/site-packages/sqlalchemy/pool.py", line 766, in _checkout
    fairy = _ConnectionRecord.checkout(pool)
  File "/Library/Frameworks/Python.framework/Versions/3.6/lib/python3.6/site-packages/sqlalchemy/pool.py", line 516, in checkout
    rec = pool._do_get()
  File "/Library/Frameworks/Python.framework/Versions/3.6/lib/python3.6/site-packages/sqlalchemy/pool.py", line 1138, in _do_get
    self._dec_overflow()
  File "/Library/Frameworks/Python.framework/Versions/3.6/lib/python3.6/site-packages/sqlalchemy/util/langhelpers.py", line 66, in __exit__
    compat.reraise(exc_type, exc_value, exc_tb)
  File "/Library/Frameworks/Python.framework/Versions/3.6/lib/python3.6/site-packages/sqlalchemy/util/compat.py", line 187, in reraise
    raise value
  File "/Library/Frameworks/Python.framework/Versions/3.6/lib/python3.6/site-packages/sqlalchemy/pool.py", line 1135, in _do_get
    return self._create_connection()
  File "/Library/Frameworks/Python.framework/Versions/3.6/lib/python3.6/site-packages/sqlalchemy/pool.py", line 333, in _create_connection
    return _ConnectionRecord(self)
  File "/Library/Frameworks/Python.framework/Versions/3.6/lib/python3.6/site-packages/sqlalchemy/pool.py", line 461, in __init__
    self.__connect(first_connect_check=True)
  File "/Library/Frameworks/Python.framework/Versions/3.6/lib/python3.6/site-packages/sqlalchemy/pool.py", line 651, in __connect
    connection = pool._invoke_creator(self)
  File "/Library/Frameworks/Python.framework/Versions/3.6/lib/python3.6/site-packages/sqlalchemy/engine/strategies.py", line 105, in connect
    return dialect.connect(*cargs, **cparams)
  File "/Library/Frameworks/Python.framework/Versions/3.6/lib/python3.6/site-packages/sqlalchemy/engine/default.py", line 393, in connect
    return self.dbapi.connect(*cargs, **cparams)
  File "/Library/Frameworks/Python.framework/Versions/3.6/lib/python3.6/site-packages/pymysql/__init__.py", line 90, in Connect
    return Connection(*args, **kwargs)
  File "/Library/Frameworks/Python.framework/Versions/3.6/lib/python3.6/site-packages/pymysql/connections.py", line 706, in __init__
    self.connect()
  File "/Library/Frameworks/Python.framework/Versions/3.6/lib/python3.6/site-packages/pymysql/connections.py", line 932, in connect
    self._request_authentication()
  File "/Library/Frameworks/Python.framework/Versions/3.6/lib/python3.6/site-packages/pymysql/connections.py", line 1152, in _request_authentication
    auth_packet = self._read_packet()
  File "/Library/Frameworks/Python.framework/Versions/3.6/lib/python3.6/site-packages/pymysql/connections.py", line 1014, in _read_packet
    packet.check_error()
  File "/Library/Frameworks/Python.framework/Versions/3.6/lib/python3.6/site-packages/pymysql/connections.py", line 393, in check_error
    err.raise_mysql_exception(self._data)
  File "/Library/Frameworks/Python.framework/Versions/3.6/lib/python3.6/site-packages/pymysql/err.py", line 107, in raise_mysql_exception
    raise errorclass(errno, errval)
pymysql.err.OperationalError: (1045, "Access denied for user 'root'@'localhost' (using password: YES)")

The above exception was the direct cause of the following exception:

Traceback (most recent call last):
  File "/Library/Frameworks/Python.framework/Versions/3.6/lib/python3.6/site-packages/apscheduler/executors/base.py", line 125, in run_job
    retval = job.func(*job.args, **job.kwargs)
  File "/Users/tianyangzhao/PycharmProjects/universal_ems/local_ems.py", line 89, in <lambda>
    session_lems),
  File "/Users/tianyangzhao/PycharmProjects/universal_ems/optimal_power_flow/main.py", line 133, in short_term_operation_lems
    database_operation.database_record(session, local_models, Target_time, "OPF")
  File "/Users/tianyangzhao/PycharmProjects/universal_ems/data_management/database_management.py", line 122, in database_record
    database_target[function].TIME_STAMP == Target_time).count() == 0:
  File "/Library/Frameworks/Python.framework/Versions/3.6/lib/python3.6/site-packages/sqlalchemy/orm/query.py", line 3089, in count
    return self.from_self(col).scalar()
  File "/Library/Frameworks/Python.framework/Versions/3.6/lib/python3.6/site-packages/sqlalchemy/orm/query.py", line 2843, in scalar
    ret = self.one()
  File "/Library/Frameworks/Python.framework/Versions/3.6/lib/python3.6/site-packages/sqlalchemy/orm/query.py", line 2814, in one
    ret = self.one_or_none()
  File "/Library/Frameworks/Python.framework/Versions/3.6/lib/python3.6/site-packages/sqlalchemy/orm/query.py", line 2784, in one_or_none
    ret = list(self)
  File "/Library/Frameworks/Python.framework/Versions/3.6/lib/python3.6/site-packages/sqlalchemy/orm/query.py", line 2855, in __iter__
    return self._execute_and_instances(context)
  File "/Library/Frameworks/Python.framework/Versions/3.6/lib/python3.6/site-packages/sqlalchemy/orm/query.py", line 2876, in _execute_and_instances
    close_with_result=True)
  File "/Library/Frameworks/Python.framework/Versions/3.6/lib/python3.6/site-packages/sqlalchemy/orm/query.py", line 2885, in _get_bind_args
    **kw
  File "/Library/Frameworks/Python.framework/Versions/3.6/lib/python3.6/site-packages/sqlalchemy/orm/query.py", line 2867, in _connection_from_session
    conn = self.session.connection(**kw)
  File "/Library/Frameworks/Python.framework/Versions/3.6/lib/python3.6/site-packages/sqlalchemy/orm/session.py", line 998, in connection
    execution_options=execution_options)
  File "/Library/Frameworks/Python.framework/Versions/3.6/lib/python3.6/site-packages/sqlalchemy/orm/session.py", line 1003, in _connection_for_bind
    engine, execution_options)
  File "/Library/Frameworks/Python.framework/Versions/3.6/lib/python3.6/site-packages/sqlalchemy/orm/session.py", line 403, in _connection_for_bind
    conn = bind.contextual_connect()
  File "/Library/Frameworks/Python.framework/Versions/3.6/lib/python3.6/site-packages/sqlalchemy/engine/base.py", line 2112, in contextual_connect
    self._wrap_pool_connect(self.pool.connect, None),
  File "/Library/Frameworks/Python.framework/Versions/3.6/lib/python3.6/site-packages/sqlalchemy/engine/base.py", line 2151, in _wrap_pool_connect
    e, dialect, self)
  File "/Library/Frameworks/Python.framework/Versions/3.6/lib/python3.6/site-packages/sqlalchemy/engine/base.py", line 1465, in _handle_dbapi_exception_noconnection
    exc_info
  File "/Library/Frameworks/Python.framework/Versions/3.6/lib/python3.6/site-packages/sqlalchemy/util/compat.py", line 203, in raise_from_cause
    reraise(type(exception), exception, tb=exc_tb, cause=cause)
  File "/Library/Frameworks/Python.framework/Versions/3.6/lib/python3.6/site-packages/sqlalchemy/util/compat.py", line 186, in reraise
    raise value.with_traceback(tb)
  File "/Library/Frameworks/Python.framework/Versions/3.6/lib/python3.6/site-packages/sqlalchemy/engine/base.py", line 2147, in _wrap_pool_connect
    return fn()
  File "/Library/Frameworks/Python.framework/Versions/3.6/lib/python3.6/site-packages/sqlalchemy/pool.py", line 387, in connect
    return _ConnectionFairy._checkout(self)
  File "/Library/Frameworks/Python.framework/Versions/3.6/lib/python3.6/site-packages/sqlalchemy/pool.py", line 766, in _checkout
    fairy = _ConnectionRecord.checkout(pool)
  File "/Library/Frameworks/Python.framework/Versions/3.6/lib/python3.6/site-packages/sqlalchemy/pool.py", line 516, in checkout
    rec = pool._do_get()
  File "/Library/Frameworks/Python.framework/Versions/3.6/lib/python3.6/site-packages/sqlalchemy/pool.py", line 1138, in _do_get
    self._dec_overflow()
  File "/Library/Frameworks/Python.framework/Versions/3.6/lib/python3.6/site-packages/sqlalchemy/util/langhelpers.py", line 66, in __exit__
    compat.reraise(exc_type, exc_value, exc_tb)
  File "/Library/Frameworks/Python.framework/Versions/3.6/lib/python3.6/site-packages/sqlalchemy/util/compat.py", line 187, in reraise
    raise value
  File "/Library/Frameworks/Python.framework/Versions/3.6/lib/python3.6/site-packages/sqlalchemy/pool.py", line 1135, in _do_get
    return self._create_connection()
  File "/Library/Frameworks/Python.framework/Versions/3.6/lib/python3.6/site-packages/sqlalchemy/pool.py", line 333, in _create_connection
    return _ConnectionRecord(self)
  File "/Library/Frameworks/Python.framework/Versions/3.6/lib/python3.6/site-packages/sqlalchemy/pool.py", line 461, in __init__
    self.__connect(first_connect_check=True)
  File "/Library/Frameworks/Python.framework/Versions/3.6/lib/python3.6/site-packages/sqlalchemy/pool.py", line 651, in __connect
    connection = pool._invoke_creator(self)
  File "/Library/Frameworks/Python.framework/Versions/3.6/lib/python3.6/site-packages/sqlalchemy/engine/strategies.py", line 105, in connect
    return dialect.connect(*cargs, **cparams)
  File "/Library/Frameworks/Python.framework/Versions/3.6/lib/python3.6/site-packages/sqlalchemy/engine/default.py", line 393, in connect
    return self.dbapi.connect(*cargs, **cparams)
  File "/Library/Frameworks/Python.framework/Versions/3.6/lib/python3.6/site-packages/pymysql/__init__.py", line 90, in Connect
    return Connection(*args, **kwargs)
  File "/Library/Frameworks/Python.framework/Versions/3.6/lib/python3.6/site-packages/pymysql/connections.py", line 706, in __init__
    self.connect()
  File "/Library/Frameworks/Python.framework/Versions/3.6/lib/python3.6/site-packages/pymysql/connections.py", line 932, in connect
    self._request_authentication()
  File "/Library/Frameworks/Python.framework/Versions/3.6/lib/python3.6/site-packages/pymysql/connections.py", line 1152, in _request_authentication
    auth_packet = self._read_packet()
  File "/Library/Frameworks/Python.framework/Versions/3.6/lib/python3.6/site-packages/pymysql/connections.py", line 1014, in _read_packet
    packet.check_error()
  File "/Library/Frameworks/Python.framework/Versions/3.6/lib/python3.6/site-packages/pymysql/connections.py", line 393, in check_error
    err.raise_mysql_exception(self._data)
  File "/Library/Frameworks/Python.framework/Versions/3.6/lib/python3.6/site-packages/pymysql/err.py", line 107, in raise_mysql_exception
    raise errorclass(errno, errval)
sqlalchemy.exc.OperationalError: (pymysql.err.OperationalError) (1045, "Access denied for user 'root'@'localhost' (using password: YES)")
Job "middle_term_operation.middle_term_operation_uems (trigger: cron[minute='*/5', second='1'], next run at: 2017-11-23 10:20:01 +08)" raised an exception
Traceback (most recent call last):
  File "/Library/Frameworks/Python.framework/Versions/3.6/lib/python3.6/site-packages/apscheduler/executors/base.py", line 125, in run_job
    retval = job.func(*job.args, **job.kwargs)
  File "/Users/tianyangzhao/PycharmProjects/universal_ems/economic_dispatch/main.py", line 63, in middle_term_operation_uems
    "Feasible")
  File "/Users/tianyangzhao/PycharmProjects/universal_ems/economic_dispatch/problem_formulation.py", line 403, in problem_formulation_universal
    local_model_mathematical = problem_formulation.problem_formulation_local(local_model)
  File "/Users/tianyangzhao/PycharmProjects/universal_ems/economic_dispatch/problem_formulation.py", line 71, in problem_formulation_local
    beq.append(model["Load_ac"]["PD"][i] + model["Load_uac"]["PD"][i])
IndexError: list index out of range
Job "run.<locals>.<lambda> (trigger: cron[minute='0-59', second='1'], next run at: 2017-11-23 10:16:01 +08)" raised an exception
Traceback (most recent call last):
  File "/Library/Frameworks/Python.framework/Versions/3.6/lib/python3.6/site-packages/apscheduler/executors/base.py", line 125, in run_job
    retval = job.func(*job.args, **job.kwargs)
  File "/Users/tianyangzhao/PycharmProjects/universal_ems/local_ems.py", line 89, in <lambda>
    session_lems),
  File "/Users/tianyangzhao/PycharmProjects/universal_ems/optimal_power_flow/main.py", line 133, in short_term_operation_lems
    database_operation.database_record(session, local_models, Target_time, "OPF")
  File "/Users/tianyangzhao/PycharmProjects/universal_ems/data_management/database_management.py", line 122, in database_record
    database_target[function].TIME_STAMP == Target_time).count() == 0:
  File "/Library/Frameworks/Python.framework/Versions/3.6/lib/python3.6/site-packages/sqlalchemy/orm/query.py", line 3089, in count
    return self.from_self(col).scalar()
  File "/Library/Frameworks/Python.framework/Versions/3.6/lib/python3.6/site-packages/sqlalchemy/orm/query.py", line 2843, in scalar
    ret = self.one()
  File "/Library/Frameworks/Python.framework/Versions/3.6/lib/python3.6/site-packages/sqlalchemy/orm/query.py", line 2814, in one
    ret = self.one_or_none()
  File "/Library/Frameworks/Python.framework/Versions/3.6/lib/python3.6/site-packages/sqlalchemy/orm/query.py", line 2784, in one_or_none
    ret = list(self)
  File "/Library/Frameworks/Python.framework/Versions/3.6/lib/python3.6/site-packages/sqlalchemy/orm/query.py", line 2854, in __iter__
    self.session._autoflush()
  File "/Library/Frameworks/Python.framework/Versions/3.6/lib/python3.6/site-packages/sqlalchemy/orm/session.py", line 1397, in _autoflush
    self.flush()
  File "/Library/Frameworks/Python.framework/Versions/3.6/lib/python3.6/site-packages/sqlalchemy/orm/session.py", line 2177, in flush
    self._flush(objects)
  File "/Library/Frameworks/Python.framework/Versions/3.6/lib/python3.6/site-packages/sqlalchemy/orm/session.py", line 2257, in _flush
    subtransactions=True)
  File "/Library/Frameworks/Python.framework/Versions/3.6/lib/python3.6/site-packages/sqlalchemy/orm/session.py", line 817, in begin
    nested=nested)
  File "/Library/Frameworks/Python.framework/Versions/3.6/lib/python3.6/site-packages/sqlalchemy/orm/session.py", line 297, in _begin
    self._assert_active()
  File "/Library/Frameworks/Python.framework/Versions/3.6/lib/python3.6/site-packages/sqlalchemy/orm/session.py", line 276, in _assert_active
    % self._rollback_exception
sqlalchemy.exc.InvalidRequestError: This Session's transaction has been rolled back due to a previous exception during flush. To begin a new transaction with this Session, first issue Session.rollback(). Original exception was: (pymysql.err.InternalError) Packet sequence number wrong - got 1 expected 6 [SQL: 'INSERT INTO mid_term_forecasting (`TIME_STAMP`, `AC_PD`, `AC_QD`, `UAC_PD`, `UAC_QD`, `DC_PD`, `UDC_PD`, `PV_PG`, `WP_PG`, `PRICE`) VALUES (%(TIME_STAMP)s, %(AC_PD)s, %(AC_QD)s, %(UAC_PD)s, %(UAC_QD)s, %(DC_PD)s, %(UDC_PD)s, %(PV_PG)s, %(WP_PG)s, %(PRICE)s)'] [parameters: {'TIME_STAMP': 1511403600, 'AC_PD': 0, 'AC_QD': 0, 'UAC_PD': 0, 'UAC_QD': 0, 'DC_PD': 0, 'UDC_PD': 0, 'PV_PG': 0, 'WP_PG': 0, 'PRICE': 0}]
Job "run.<locals>.<lambda> (trigger: cron[minute='*/5', second='1'], next run at: 2017-11-23 10:20:01 +08)" raised an exception
Traceback (most recent call last):
  File "/Library/Frameworks/Python.framework/Versions/3.6/lib/python3.6/site-packages/apscheduler/executors/base.py", line 125, in run_job
    retval = job.func(*job.args, **job.kwargs)
  File "/Users/tianyangzhao/PycharmProjects/universal_ems/local_ems.py", line 98, in <lambda>
    session_lems),
  File "/Users/tianyangzhao/PycharmProjects/universal_ems/economic_dispatch/main.py", line 125, in middle_term_operation_lems
    dynamic_model = information_formulation_extraction_dynamic.info_formulation(local_models, Target_time, "ED")
  File "/Users/tianyangzhao/PycharmProjects/universal_ems/data_management/information_management.py", line 313, in info_formulation
    load_ac_info.PD.extend(model["Load_ac"]["PD"])
  File "/Library/Frameworks/Python.framework/Versions/3.6/lib/python3.6/site-packages/google/protobuf/internal/containers.py", line 267, in extend
    elem_seq_iter = iter(elem_seq)
TypeError: 'int' object is not iterable
Execution of job "run.<locals>.<lambda> (trigger: cron[minute='0-59', second='1'], next run at: 2017-11-23 10:21:01 +08)" skipped: maximum number of running instances reached (1)
Execution of job "short_term_operation.short_term_operation_uems (trigger: cron[minute='0-59', second='1'], next run at: 2017-11-23 10:21:01 +08)" skipped: maximum number of running instances reached (1)
Job "run.<locals>.<lambda> (trigger: cron[minute='0-59', second='1'], next run at: 2017-11-23 10:26:01 +08)" raised an exception
Traceback (most recent call last):
  File "/Library/Frameworks/Python.framework/Versions/3.6/lib/python3.6/site-packages/sqlalchemy/engine/base.py", line 1182, in _execute_context
    context)
  File "/Library/Frameworks/Python.framework/Versions/3.6/lib/python3.6/site-packages/sqlalchemy/engine/default.py", line 470, in do_execute
    cursor.execute(statement, parameters)
  File "/Library/Frameworks/Python.framework/Versions/3.6/lib/python3.6/site-packages/pymysql/cursors.py", line 166, in execute
    result = self._query(query)
  File "/Library/Frameworks/Python.framework/Versions/3.6/lib/python3.6/site-packages/pymysql/cursors.py", line 322, in _query
    conn.query(q)
  File "/Library/Frameworks/Python.framework/Versions/3.6/lib/python3.6/site-packages/pymysql/connections.py", line 856, in query
    self._affected_rows = self._read_query_result(unbuffered=unbuffered)
  File "/Library/Frameworks/Python.framework/Versions/3.6/lib/python3.6/site-packages/pymysql/connections.py", line 1057, in _read_query_result
    result.read()
  File "/Library/Frameworks/Python.framework/Versions/3.6/lib/python3.6/site-packages/pymysql/connections.py", line 1340, in read
    first_packet = self.connection._read_packet()
  File "/Library/Frameworks/Python.framework/Versions/3.6/lib/python3.6/site-packages/pymysql/connections.py", line 1014, in _read_packet
    packet.check_error()
  File "/Library/Frameworks/Python.framework/Versions/3.6/lib/python3.6/site-packages/pymysql/connections.py", line 393, in check_error
    err.raise_mysql_exception(self._data)
  File "/Library/Frameworks/Python.framework/Versions/3.6/lib/python3.6/site-packages/pymysql/err.py", line 107, in raise_mysql_exception
    raise errorclass(errno, errval)
pymysql.err.InternalError: (1241, 'Operand should contain 1 column(s)')

The above exception was the direct cause of the following exception:

Traceback (most recent call last):
  File "/Library/Frameworks/Python.framework/Versions/3.6/lib/python3.6/site-packages/apscheduler/executors/base.py", line 125, in run_job
    retval = job.func(*job.args, **job.kwargs)
  File "/Users/tianyangzhao/PycharmProjects/universal_ems/local_ems.py", line 97, in <lambda>
    session_lems_short),
  File "/Users/tianyangzhao/PycharmProjects/universal_ems/optimal_power_flow/main.py", line 133, in short_term_operation_lems
    database_operation.database_record(session, local_models, Target_time, "OPF")
  File "/Users/tianyangzhao/PycharmProjects/universal_ems/data_management/database_management.py", line 157, in database_record
    session.commit()
  File "/Library/Frameworks/Python.framework/Versions/3.6/lib/python3.6/site-packages/sqlalchemy/orm/session.py", line 906, in commit
    self.transaction.commit()
  File "/Library/Frameworks/Python.framework/Versions/3.6/lib/python3.6/site-packages/sqlalchemy/orm/session.py", line 461, in commit
    self._prepare_impl()
  File "/Library/Frameworks/Python.framework/Versions/3.6/lib/python3.6/site-packages/sqlalchemy/orm/session.py", line 441, in _prepare_impl
    self.session.flush()
  File "/Library/Frameworks/Python.framework/Versions/3.6/lib/python3.6/site-packages/sqlalchemy/orm/session.py", line 2177, in flush
    self._flush(objects)
  File "/Library/Frameworks/Python.framework/Versions/3.6/lib/python3.6/site-packages/sqlalchemy/orm/session.py", line 2297, in _flush
    transaction.rollback(_capture_exception=True)
  File "/Library/Frameworks/Python.framework/Versions/3.6/lib/python3.6/site-packages/sqlalchemy/util/langhelpers.py", line 66, in __exit__
    compat.reraise(exc_type, exc_value, exc_tb)
  File "/Library/Frameworks/Python.framework/Versions/3.6/lib/python3.6/site-packages/sqlalchemy/util/compat.py", line 187, in reraise
    raise value
  File "/Library/Frameworks/Python.framework/Versions/3.6/lib/python3.6/site-packages/sqlalchemy/orm/session.py", line 2261, in _flush
    flush_context.execute()
  File "/Library/Frameworks/Python.framework/Versions/3.6/lib/python3.6/site-packages/sqlalchemy/orm/unitofwork.py", line 389, in execute
    rec.execute(self)
  File "/Library/Frameworks/Python.framework/Versions/3.6/lib/python3.6/site-packages/sqlalchemy/orm/unitofwork.py", line 548, in execute
    uow
  File "/Library/Frameworks/Python.framework/Versions/3.6/lib/python3.6/site-packages/sqlalchemy/orm/persistence.py", line 177, in save_obj
    mapper, table, update)
  File "/Library/Frameworks/Python.framework/Versions/3.6/lib/python3.6/site-packages/sqlalchemy/orm/persistence.py", line 737, in _emit_update_statements
    execute(statement, multiparams)
  File "/Library/Frameworks/Python.framework/Versions/3.6/lib/python3.6/site-packages/sqlalchemy/engine/base.py", line 945, in execute
    return meth(self, multiparams, params)
  File "/Library/Frameworks/Python.framework/Versions/3.6/lib/python3.6/site-packages/sqlalchemy/sql/elements.py", line 263, in _execute_on_connection
    return connection._execute_clauseelement(self, multiparams, params)
  File "/Library/Frameworks/Python.framework/Versions/3.6/lib/python3.6/site-packages/sqlalchemy/engine/base.py", line 1053, in _execute_clauseelement
    compiled_sql, distilled_params
  File "/Library/Frameworks/Python.framework/Versions/3.6/lib/python3.6/site-packages/sqlalchemy/engine/base.py", line 1189, in _execute_context
    context)
  File "/Library/Frameworks/Python.framework/Versions/3.6/lib/python3.6/site-packages/sqlalchemy/engine/base.py", line 1402, in _handle_dbapi_exception
    exc_info
  File "/Library/Frameworks/Python.framework/Versions/3.6/lib/python3.6/site-packages/sqlalchemy/util/compat.py", line 203, in raise_from_cause
    reraise(type(exception), exception, tb=exc_tb, cause=cause)
  File "/Library/Frameworks/Python.framework/Versions/3.6/lib/python3.6/site-packages/sqlalchemy/util/compat.py", line 186, in reraise
    raise value.with_traceback(tb)
  File "/Library/Frameworks/Python.framework/Versions/3.6/lib/python3.6/site-packages/sqlalchemy/engine/base.py", line 1182, in _execute_context
    context)
  File "/Library/Frameworks/Python.framework/Versions/3.6/lib/python3.6/site-packages/sqlalchemy/engine/default.py", line 470, in do_execute
    cursor.execute(statement, parameters)
  File "/Library/Frameworks/Python.framework/Versions/3.6/lib/python3.6/site-packages/pymysql/cursors.py", line 166, in execute
    result = self._query(query)
  File "/Library/Frameworks/Python.framework/Versions/3.6/lib/python3.6/site-packages/pymysql/cursors.py", line 322, in _query
    conn.query(q)
  File "/Library/Frameworks/Python.framework/Versions/3.6/lib/python3.6/site-packages/pymysql/connections.py", line 856, in query
    self._affected_rows = self._read_query_result(unbuffered=unbuffered)
  File "/Library/Frameworks/Python.framework/Versions/3.6/lib/python3.6/site-packages/pymysql/connections.py", line 1057, in _read_query_result
    result.read()
  File "/Library/Frameworks/Python.framework/Versions/3.6/lib/python3.6/site-packages/pymysql/connections.py", line 1340, in read
    first_packet = self.connection._read_packet()
  File "/Library/Frameworks/Python.framework/Versions/3.6/lib/python3.6/site-packages/pymysql/connections.py", line 1014, in _read_packet
    packet.check_error()
  File "/Library/Frameworks/Python.framework/Versions/3.6/lib/python3.6/site-packages/pymysql/connections.py", line 393, in check_error
    err.raise_mysql_exception(self._data)
  File "/Library/Frameworks/Python.framework/Versions/3.6/lib/python3.6/site-packages/pymysql/err.py", line 107, in raise_mysql_exception
    raise errorclass(errno, errval)
sqlalchemy.exc.InternalError: (pymysql.err.InternalError) (1241, 'Operand should contain 1 column(s)') [SQL: 'UPDATE short_term_operation SET `AC_PD`=%(AC_PD)s, `UAC_PD`=%(UAC_PD)s, `DC_PD`=%(DC_PD)s, `UDC_PD`=%(UDC_PD)s, `PV_PG`=%(PV_PG)s, `WP_PG`=%(WP_PG)s, `DG_STATUS`=%(DG_STATUS)s, `UG_STATUS`=%(UG_STATUS)s, `BIC_PG`=%(BIC_PG)s, `BAT_SOC`=%(BAT_SOC)s, `PMG`=%(PMG)s WHERE short_term_operation.`TIME_STAMP` = %(short_term_operation_TIME_STAMP)s'] [parameters: {'AC_PD': [833, 756, 469, 806, 121, 358, 72, 603, 36, 622, 963, 238], 'UAC_PD': [930, 570, 177, 577, 449, 14, 730, 543, 141, 281, 193, 267], 'DC_PD': 410, 'UDC_PD': 196, 'PV_PG': [0, 0, 0, 0, 0, 0, 0, 0, 0, 0, 0, 0], 'WP_PG': [0, 0, 0, 0, 0, 0, 0, 0, 0, 0, 0, 0], 'DG_STATUS': b'\x00', 'UG_STATUS': b'', 'BIC_PG': 1416.0, 'BAT_SOC': 0.5, 'PMG': 740, 'short_term_operation_TIME_STAMP': 1511403960}]
Job "middle_term_operation.middle_term_operation_uems (trigger: cron[minute='*/5', second='1'], next run at: 2017-11-23 10:30:01 +08)" raised an exception
Traceback (most recent call last):
  File "/Library/Frameworks/Python.framework/Versions/3.6/lib/python3.6/site-packages/apscheduler/executors/base.py", line 125, in run_job
    retval = job.func(*job.args, **job.kwargs)
  File "/Users/tianyangzhao/PycharmProjects/universal_ems/economic_dispatch/main.py", line 63, in middle_term_operation_uems
    "Feasible")
  File "/Users/tianyangzhao/PycharmProjects/universal_ems/economic_dispatch/problem_formulation.py", line 403, in problem_formulation_universal
    local_model_mathematical = problem_formulation.problem_formulation_local(local_model)
  File "/Users/tianyangzhao/PycharmProjects/universal_ems/economic_dispatch/problem_formulation.py", line 71, in problem_formulation_local
    beq.append(model["Load_ac"]["PD"][i] + model["Load_uac"]["PD"][i])
TypeError: unsupported operand type(s) for +: 'RepeatedScalarFieldContainer' and 'RepeatedScalarFieldContainer'
Job "run.<locals>.<lambda> (trigger: cron[minute='0-59', second='1'], next run at: 2017-11-23 10:27:01 +08)" raised an exception
Traceback (most recent call last):
  File "/Library/Frameworks/Python.framework/Versions/3.6/lib/python3.6/site-packages/apscheduler/executors/base.py", line 125, in run_job
    retval = job.func(*job.args, **job.kwargs)
  File "/Users/tianyangzhao/PycharmProjects/universal_ems/local_ems.py", line 97, in <lambda>
    session_lems_short),
  File "/Users/tianyangzhao/PycharmProjects/universal_ems/optimal_power_flow/main.py", line 133, in short_term_operation_lems
    database_operation.database_record(session, local_models, Target_time, "OPF")
  File "/Users/tianyangzhao/PycharmProjects/universal_ems/data_management/database_management.py", line 122, in database_record
    database_target[function].TIME_STAMP == Target_time).count() == 0:
  File "/Library/Frameworks/Python.framework/Versions/3.6/lib/python3.6/site-packages/sqlalchemy/orm/query.py", line 3089, in count
    return self.from_self(col).scalar()
  File "/Library/Frameworks/Python.framework/Versions/3.6/lib/python3.6/site-packages/sqlalchemy/orm/query.py", line 2843, in scalar
    ret = self.one()
  File "/Library/Frameworks/Python.framework/Versions/3.6/lib/python3.6/site-packages/sqlalchemy/orm/query.py", line 2814, in one
    ret = self.one_or_none()
  File "/Library/Frameworks/Python.framework/Versions/3.6/lib/python3.6/site-packages/sqlalchemy/orm/query.py", line 2784, in one_or_none
    ret = list(self)
  File "/Library/Frameworks/Python.framework/Versions/3.6/lib/python3.6/site-packages/sqlalchemy/orm/query.py", line 2855, in __iter__
    return self._execute_and_instances(context)
  File "/Library/Frameworks/Python.framework/Versions/3.6/lib/python3.6/site-packages/sqlalchemy/orm/query.py", line 2876, in _execute_and_instances
    close_with_result=True)
  File "/Library/Frameworks/Python.framework/Versions/3.6/lib/python3.6/site-packages/sqlalchemy/orm/query.py", line 2885, in _get_bind_args
    **kw
  File "/Library/Frameworks/Python.framework/Versions/3.6/lib/python3.6/site-packages/sqlalchemy/orm/query.py", line 2867, in _connection_from_session
    conn = self.session.connection(**kw)
  File "/Library/Frameworks/Python.framework/Versions/3.6/lib/python3.6/site-packages/sqlalchemy/orm/session.py", line 998, in connection
    execution_options=execution_options)
  File "/Library/Frameworks/Python.framework/Versions/3.6/lib/python3.6/site-packages/sqlalchemy/orm/session.py", line 1003, in _connection_for_bind
    engine, execution_options)
  File "/Library/Frameworks/Python.framework/Versions/3.6/lib/python3.6/site-packages/sqlalchemy/orm/session.py", line 382, in _connection_for_bind
    self._assert_active()
  File "/Library/Frameworks/Python.framework/Versions/3.6/lib/python3.6/site-packages/sqlalchemy/orm/session.py", line 276, in _assert_active
    % self._rollback_exception
sqlalchemy.exc.InvalidRequestError: This Session's transaction has been rolled back due to a previous exception during flush. To begin a new transaction with this Session, first issue Session.rollback(). Original exception was: (pymysql.err.InternalError) (1241, 'Operand should contain 1 column(s)') [SQL: 'UPDATE short_term_operation SET `AC_PD`=%(AC_PD)s, `UAC_PD`=%(UAC_PD)s, `DC_PD`=%(DC_PD)s, `UDC_PD`=%(UDC_PD)s, `PV_PG`=%(PV_PG)s, `WP_PG`=%(WP_PG)s, `DG_STATUS`=%(DG_STATUS)s, `UG_STATUS`=%(UG_STATUS)s, `BIC_PG`=%(BIC_PG)s, `BAT_SOC`=%(BAT_SOC)s, `PMG`=%(PMG)s WHERE short_term_operation.`TIME_STAMP` = %(short_term_operation_TIME_STAMP)s'] [parameters: {'AC_PD': [833, 756, 469, 806, 121, 358, 72, 603, 36, 622, 963, 238], 'UAC_PD': [930, 570, 177, 577, 449, 14, 730, 543, 141, 281, 193, 267], 'DC_PD': 410, 'UDC_PD': 196, 'PV_PG': [0, 0, 0, 0, 0, 0, 0, 0, 0, 0, 0, 0], 'WP_PG': [0, 0, 0, 0, 0, 0, 0, 0, 0, 0, 0, 0], 'DG_STATUS': b'\x00', 'UG_STATUS': b'', 'BIC_PG': 1416.0, 'BAT_SOC': 0.5, 'PMG': 740, 'short_term_operation_TIME_STAMP': 1511403960}]
Job "middle_term_operation.middle_term_operation_uems (trigger: cron[minute='*/5', second='1'], next run at: 2017-11-23 10:35:01 +08)" raised an exception
Traceback (most recent call last):
  File "/Library/Frameworks/Python.framework/Versions/3.6/lib/python3.6/site-packages/apscheduler/executors/base.py", line 125, in run_job
    retval = job.func(*job.args, **job.kwargs)
  File "/Users/tianyangzhao/PycharmProjects/universal_ems/economic_dispatch/main.py", line 63, in middle_term_operation_uems
    "Feasible")
  File "/Users/tianyangzhao/PycharmProjects/universal_ems/economic_dispatch/problem_formulation.py", line 403, in problem_formulation_universal
    local_model_mathematical = problem_formulation.problem_formulation_local(local_model)
  File "/Users/tianyangzhao/PycharmProjects/universal_ems/economic_dispatch/problem_formulation.py", line 71, in problem_formulation_local
    beq.append(model["Load_ac"]["PD"][i] + model["Load_uac"]["PD"][i])
TypeError: unsupported operand type(s) for +: 'RepeatedScalarFieldContainer' and 'RepeatedScalarFieldContainer'
Job "long_term_operation.long_term_operation_uems (trigger: cron[minute='*/30', second='1'], next run at: 2017-11-23 11:00:01 +08)" raised an exception
Traceback (most recent call last):
  File "/Library/Frameworks/Python.framework/Versions/3.6/lib/python3.6/site-packages/apscheduler/executors/base.py", line 125, in run_job
    retval = job.func(*job.args, **job.kwargs)
  File "/Users/tianyangzhao/PycharmProjects/universal_ems/unit_commitment/main.py", line 59, in long_term_operation_uems
    "Feasible")
  File "/Users/tianyangzhao/PycharmProjects/universal_ems/unit_commitment/problem_formulation.py", line 423, in problem_formulation_universal
    local_model_mathematical = problem_formulation.problem_formulation_local(local_model)
  File "/Users/tianyangzhao/PycharmProjects/universal_ems/unit_commitment/problem_formulation.py", line 80, in problem_formulation_local
    beq.append(model["Load_ac"]["PD"][i] + model["Load_uac"]["PD"][i])
TypeError: unsupported operand type(s) for +: 'RepeatedScalarFieldContainer' and 'RepeatedScalarFieldContainer'
Job "middle_term_operation.middle_term_operation_uems (trigger: cron[minute='*/5', second='1'], next run at: 2017-11-23 10:40:01 +08)" raised an exception
Traceback (most recent call last):
  File "/Library/Frameworks/Python.framework/Versions/3.6/lib/python3.6/site-packages/apscheduler/executors/base.py", line 125, in run_job
    retval = job.func(*job.args, **job.kwargs)
  File "/Users/tianyangzhao/PycharmProjects/universal_ems/economic_dispatch/main.py", line 63, in middle_term_operation_uems
    "Feasible")
  File "/Users/tianyangzhao/PycharmProjects/universal_ems/economic_dispatch/problem_formulation.py", line 403, in problem_formulation_universal
    local_model_mathematical = problem_formulation.problem_formulation_local(local_model)
  File "/Users/tianyangzhao/PycharmProjects/universal_ems/economic_dispatch/problem_formulation.py", line 71, in problem_formulation_local
    beq.append(model["Load_ac"]["PD"][i] + model["Load_uac"]["PD"][i])
IndexError: list index out of range
Execution of job "run.<locals>.<lambda> (trigger: cron[minute='*/5', second='5'], next run at: 2017-11-23 10:35:05 +08)" skipped: maximum number of running instances reached (1)
Run time of job "short_term_operation.short_term_operation_uems (trigger: cron[minute='0-59', second='1'], next run at: 2017-11-23 10:39:01 +08)" was missed by 0:00:23.759382
Run time of job "run.<locals>.<lambda> (trigger: cron[minute='0-59', second='1'], next run at: 2017-11-23 10:39:01 +08)" was missed by 0:00:23.759421
Job "middle_term_operation.middle_term_operation_uems (trigger: cron[minute='*/5', second='1'], next run at: 2017-11-23 11:10:01 +08)" raised an exception
Traceback (most recent call last):
  File "/Library/Frameworks/Python.framework/Versions/3.6/lib/python3.6/site-packages/apscheduler/executors/base.py", line 125, in run_job
    retval = job.func(*job.args, **job.kwargs)
  File "/Users/tianyangzhao/PycharmProjects/universal_ems/economic_dispatch/main.py", line 28, in middle_term_operation_uems
    from economic_dispatch.problem_formulation import problem_formulation
  File "/Users/tianyangzhao/PycharmProjects/universal_ems/economic_dispatch/problem_formulation.py", line 5, in <module>
    from numpy import array, vstack, zeros
  File "/Library/Frameworks/Python.framework/Versions/3.6/lib/python3.6/site-packages/numpy/__init__.py", line 152, in <module>
    test = testing.nosetester._numpy_tester().test
NameError: name 'testing' is not defined
Job "short_term_operation.short_term_operation_uems (trigger: cron[minute='0-59', second='1'], next run at: 2017-11-23 11:06:01 +08)" raised an exception
Traceback (most recent call last):
  File "/Library/Frameworks/Python.framework/Versions/3.6/lib/python3.6/site-packages/apscheduler/executors/base.py", line 125, in run_job
    retval = job.func(*job.args, **job.kwargs)
  File "/Users/tianyangzhao/PycharmProjects/universal_ems/optimal_power_flow/main.py", line 22, in short_term_operation_uems
    from optimal_power_flow.problem_solving import Solving_Thread
  File "/Users/tianyangzhao/PycharmProjects/universal_ems/optimal_power_flow/problem_solving.py", line 3, in <module>
    from scipy import optimize  # linear programming solver
  File "/Library/Frameworks/Python.framework/Versions/3.6/lib/python3.6/site-packages/scipy/__init__.py", line 61, in <module>
    from numpy import show_config as show_numpy_config
  File "/Library/Frameworks/Python.framework/Versions/3.6/lib/python3.6/site-packages/numpy/__init__.py", line 152, in <module>
    test = testing.nosetester._numpy_tester().test
NameError: name 'testing' is not defined
Execution of job "run.<locals>.<lambda> (trigger: cron[minute='0-59', second='1'], next run at: 2017-11-23 11:06:01 +08)" skipped: maximum number of running instances reached (1)
Job "short_term_operation.short_term_operation_uems (trigger: cron[minute='0-59', second='1'], next run at: 2017-11-23 11:07:01 +08)" raised an exception
Traceback (most recent call last):
  File "/Library/Frameworks/Python.framework/Versions/3.6/lib/python3.6/site-packages/apscheduler/executors/base.py", line 125, in run_job
    retval = job.func(*job.args, **job.kwargs)
  File "/Users/tianyangzhao/PycharmProjects/universal_ems/optimal_power_flow/main.py", line 22, in short_term_operation_uems
    from optimal_power_flow.problem_solving import Solving_Thread
  File "/Users/tianyangzhao/PycharmProjects/universal_ems/optimal_power_flow/problem_solving.py", line 3, in <module>
    from scipy import optimize  # linear programming solver
  File "/Library/Frameworks/Python.framework/Versions/3.6/lib/python3.6/site-packages/scipy/__init__.py", line 61, in <module>
    from numpy import show_config as show_numpy_config
  File "/Library/Frameworks/Python.framework/Versions/3.6/lib/python3.6/site-packages/numpy/__init__.py", line 152, in <module>
    test = testing.nosetester._numpy_tester().test
NameError: name 'testing' is not defined
Execution of job "run.<locals>.<lambda> (trigger: cron[minute='0-59', second='1'], next run at: 2017-11-23 11:07:01 +08)" skipped: maximum number of running instances reached (1)
Job "short_term_operation.short_term_operation_uems (trigger: cron[minute='0-59', second='1'], next run at: 2017-11-23 11:08:01 +08)" raised an exception
Traceback (most recent call last):
  File "/Library/Frameworks/Python.framework/Versions/3.6/lib/python3.6/site-packages/apscheduler/executors/base.py", line 125, in run_job
    retval = job.func(*job.args, **job.kwargs)
  File "/Users/tianyangzhao/PycharmProjects/universal_ems/optimal_power_flow/main.py", line 22, in short_term_operation_uems
    from optimal_power_flow.problem_solving import Solving_Thread
  File "/Users/tianyangzhao/PycharmProjects/universal_ems/optimal_power_flow/problem_solving.py", line 3, in <module>
    from scipy import optimize  # linear programming solver
  File "/Library/Frameworks/Python.framework/Versions/3.6/lib/python3.6/site-packages/scipy/__init__.py", line 61, in <module>
    from numpy import show_config as show_numpy_config
  File "/Library/Frameworks/Python.framework/Versions/3.6/lib/python3.6/site-packages/numpy/__init__.py", line 152, in <module>
    test = testing.nosetester._numpy_tester().test
NameError: name 'testing' is not defined
Job "middle_term_operation.middle_term_operation_uems (trigger: cron[minute='*/5', second='1'], next run at: 2017-11-23 11:15:01 +08)" raised an exception
Traceback (most recent call last):
  File "/Library/Frameworks/Python.framework/Versions/3.6/lib/python3.6/site-packages/apscheduler/executors/base.py", line 125, in run_job
    retval = job.func(*job.args, **job.kwargs)
  File "/Users/tianyangzhao/PycharmProjects/universal_ems/economic_dispatch/main.py", line 63, in middle_term_operation_uems
    "Feasible")
  File "/Users/tianyangzhao/PycharmProjects/universal_ems/economic_dispatch/problem_formulation.py", line 403, in problem_formulation_universal
    local_model_mathematical = problem_formulation.problem_formulation_local(local_model)
  File "/Users/tianyangzhao/PycharmProjects/universal_ems/economic_dispatch/problem_formulation.py", line 71, in problem_formulation_local
    beq.append(model["Load_ac"]["PD"][i] + model["Load_uac"]["PD"][i])
TypeError: unsupported operand type(s) for +: 'RepeatedScalarFieldContainer' and 'RepeatedScalarFieldContainer'
Job "middle_term_operation.middle_term_operation_uems (trigger: cron[minute='*/5', second='1'], next run at: 2017-11-23 11:20:01 +08)" raised an exception
Traceback (most recent call last):
  File "/Library/Frameworks/Python.framework/Versions/3.6/lib/python3.6/site-packages/apscheduler/executors/base.py", line 125, in run_job
    retval = job.func(*job.args, **job.kwargs)
  File "/Users/tianyangzhao/PycharmProjects/universal_ems/economic_dispatch/main.py", line 63, in middle_term_operation_uems
    "Feasible")
  File "/Users/tianyangzhao/PycharmProjects/universal_ems/economic_dispatch/problem_formulation.py", line 403, in problem_formulation_universal
    local_model_mathematical = problem_formulation.problem_formulation_local(local_model)
  File "/Users/tianyangzhao/PycharmProjects/universal_ems/economic_dispatch/problem_formulation.py", line 71, in problem_formulation_local
    beq.append(model["Load_ac"]["PD"][i] + model["Load_uac"]["PD"][i])
IndexError: list index out of range
Execution of job "run.<locals>.<lambda> (trigger: cron[minute='*/5', second='5'], next run at: 2017-11-23 11:15:05 +08)" skipped: maximum number of running instances reached (1)
Job "middle_term_operation.middle_term_operation_uems (trigger: cron[minute='*/5', second='1'], next run at: 2017-11-23 11:25:01 +08)" raised an exception
Traceback (most recent call last):
  File "/Library/Frameworks/Python.framework/Versions/3.6/lib/python3.6/site-packages/apscheduler/executors/base.py", line 125, in run_job
    retval = job.func(*job.args, **job.kwargs)
  File "/Users/tianyangzhao/PycharmProjects/universal_ems/economic_dispatch/main.py", line 63, in middle_term_operation_uems
    "Feasible")
  File "/Users/tianyangzhao/PycharmProjects/universal_ems/economic_dispatch/problem_formulation.py", line 403, in problem_formulation_universal
    local_model_mathematical = problem_formulation.problem_formulation_local(local_model)
  File "/Users/tianyangzhao/PycharmProjects/universal_ems/economic_dispatch/problem_formulation.py", line 71, in problem_formulation_local
    beq.append(model["Load_ac"]["PD"][i] + model["Load_uac"]["PD"][i])
IndexError: list index out of range
Execution of job "run.<locals>.<lambda> (trigger: cron[minute='*/5', second='5'], next run at: 2017-11-23 11:20:05 +08)" skipped: maximum number of running instances reached (1)
Execution of job "run.<locals>.<lambda> (trigger: cron[minute='*/5', second='5'], next run at: 2017-11-23 11:25:05 +08)" skipped: maximum number of running instances reached (1)
Run time of job "short_term_operation.short_term_operation_uems (trigger: cron[minute='0-59', second='1'], next run at: 2017-11-23 11:55:01 +08)" was missed by 0:00:48.364803
Run time of job "run.<locals>.<lambda> (trigger: cron[minute='0-59', second='1'], next run at: 2017-11-23 11:55:01 +08)" was missed by 0:00:48.364305
Run time of job "run.<locals>.<lambda> (trigger: cron[minute='*/30', second='30'], next run at: 2017-11-23 12:00:30 +08)" was missed by 0:24:19.365221
Run time of job "middle_term_operation.middle_term_operation_uems (trigger: cron[minute='*/5', second='1'], next run at: 2017-11-23 11:55:01 +08)" was missed by 0:04:48.365053
Run time of job "long_term_operation.long_term_operation_uems (trigger: cron[minute='*/30', second='1'], next run at: 2017-11-23 12:00:01 +08)" was missed by 0:24:48.365176
Job "middle_term_operation.middle_term_operation_uems (trigger: cron[minute='*/5', second='1'], next run at: 2017-11-23 12:10:01 +08)" raised an exception
Traceback (most recent call last):
  File "/Library/Frameworks/Python.framework/Versions/3.6/lib/python3.6/site-packages/apscheduler/executors/base.py", line 125, in run_job
    retval = job.func(*job.args, **job.kwargs)
  File "/Users/tianyangzhao/PycharmProjects/universal_ems/economic_dispatch/main.py", line 63, in middle_term_operation_uems
    "Feasible")
  File "/Users/tianyangzhao/PycharmProjects/universal_ems/economic_dispatch/problem_formulation.py", line 403, in problem_formulation_universal
    local_model_mathematical = problem_formulation.problem_formulation_local(local_model)
  File "/Users/tianyangzhao/PycharmProjects/universal_ems/economic_dispatch/problem_formulation.py", line 71, in problem_formulation_local
    beq.append(model["Load_ac"]["PD"][i] + model["Load_uac"]["PD"][i])
TypeError: unsupported operand type(s) for +: 'RepeatedScalarFieldContainer' and 'RepeatedScalarFieldContainer'
Job "middle_term_operation.middle_term_operation_uems (trigger: cron[minute='*/5', second='1'], next run at: 2017-11-23 12:15:01 +08)" raised an exception
Traceback (most recent call last):
  File "/Library/Frameworks/Python.framework/Versions/3.6/lib/python3.6/site-packages/apscheduler/executors/base.py", line 125, in run_job
    retval = job.func(*job.args, **job.kwargs)
  File "/Users/tianyangzhao/PycharmProjects/universal_ems/economic_dispatch/main.py", line 63, in middle_term_operation_uems
    "Feasible")
  File "/Users/tianyangzhao/PycharmProjects/universal_ems/economic_dispatch/problem_formulation.py", line 403, in problem_formulation_universal
    local_model_mathematical = problem_formulation.problem_formulation_local(local_model)
  File "/Users/tianyangzhao/PycharmProjects/universal_ems/economic_dispatch/problem_formulation.py", line 71, in problem_formulation_local
    beq.append(model["Load_ac"]["PD"][i] + model["Load_uac"]["PD"][i])
TypeError: unsupported operand type(s) for +: 'RepeatedScalarFieldContainer' and 'RepeatedScalarFieldContainer'
Job "middle_term_operation.middle_term_operation_uems (trigger: cron[minute='*/5', second='1'], next run at: 2017-11-23 12:20:01 +08)" raised an exception
Traceback (most recent call last):
  File "/Library/Frameworks/Python.framework/Versions/3.6/lib/python3.6/site-packages/apscheduler/executors/base.py", line 125, in run_job
    retval = job.func(*job.args, **job.kwargs)
  File "/Users/tianyangzhao/PycharmProjects/universal_ems/economic_dispatch/main.py", line 63, in middle_term_operation_uems
    "Feasible")
  File "/Users/tianyangzhao/PycharmProjects/universal_ems/economic_dispatch/problem_formulation.py", line 403, in problem_formulation_universal
    local_model_mathematical = problem_formulation.problem_formulation_local(local_model)
  File "/Users/tianyangzhao/PycharmProjects/universal_ems/economic_dispatch/problem_formulation.py", line 71, in problem_formulation_local
    beq.append(model["Load_ac"]["PD"][i] + model["Load_uac"]["PD"][i])
IndexError: list index out of range
Execution of job "run.<locals>.<lambda> (trigger: cron[minute='*/5', second='5'], next run at: 2017-11-23 12:15:05 +08)" skipped: maximum number of running instances reached (1)
Job "middle_term_operation.middle_term_operation_uems (trigger: cron[minute='*/1', second='5'], next run at: 2017-11-23 12:20:05 +08)" raised an exception
Traceback (most recent call last):
  File "/Library/Frameworks/Python.framework/Versions/3.6/lib/python3.6/site-packages/apscheduler/executors/base.py", line 125, in run_job
    retval = job.func(*job.args, **job.kwargs)
  File "/Users/tianyangzhao/PycharmProjects/universal_ems/economic_dispatch/main.py", line 63, in middle_term_operation_uems
    "Feasible")
  File "/Users/tianyangzhao/PycharmProjects/universal_ems/economic_dispatch/problem_formulation.py", line 403, in problem_formulation_universal
    local_model_mathematical = problem_formulation.problem_formulation_local(local_model)
  File "/Users/tianyangzhao/PycharmProjects/universal_ems/economic_dispatch/problem_formulation.py", line 71, in problem_formulation_local
    beq.append(model["Load_ac"]["PD"][i] + model["Load_uac"]["PD"][i])
TypeError: unsupported operand type(s) for +: 'RepeatedScalarFieldContainer' and 'RepeatedScalarFieldContainer'
Job "run.<locals>.<lambda> (trigger: cron[minute='*/1', second='5'], next run at: 2017-11-23 13:11:05 +08)" raised an exception
Traceback (most recent call last):
  File "/Library/Frameworks/Python.framework/Versions/3.6/lib/python3.6/site-packages/apscheduler/executors/base.py", line 125, in run_job
    retval = job.func(*job.args, **job.kwargs)
  File "/Users/tianyangzhao/PycharmProjects/universal_ems/local_ems.py", line 106, in <lambda>
    session_lems_middle),
  File "/Users/tianyangzhao/PycharmProjects/universal_ems/economic_dispatch/main.py", line 125, in middle_term_operation_lems
    dynamic_model = information_formulation_extraction_dynamic.info_formulation(local_models, Target_time, "ED")
  File "/Users/tianyangzhao/PycharmProjects/universal_ems/data_management/information_management.py", line 238, in info_formulation
    ug_info.PG.extend([model["UG"]["COMMAND_PG"]])
  File "/Library/Frameworks/Python.framework/Versions/3.6/lib/python3.6/site-packages/google/protobuf/internal/containers.py", line 275, in extend
    new_values = [self._type_checker.CheckValue(elem) for elem in elem_seq_iter]
  File "/Library/Frameworks/Python.framework/Versions/3.6/lib/python3.6/site-packages/google/protobuf/internal/containers.py", line 275, in <listcomp>
    new_values = [self._type_checker.CheckValue(elem) for elem in elem_seq_iter]
  File "/Library/Frameworks/Python.framework/Versions/3.6/lib/python3.6/site-packages/google/protobuf/internal/type_checkers.py", line 133, in CheckValue
    raise TypeError(message)
TypeError: [3000, 3000, 1200, 2461, 2721, 3000, 3000, 3000, 3000, 2759, 1979, 2383] has type <class 'google.protobuf.internal.containers.RepeatedScalarFieldContainer'>, but expected one of: (<class 'int'>,)
Execution of job "middle_term_operation.middle_term_operation_uems (trigger: cron[minute='*/1', second='5'], next run at: 2017-11-23 13:11:05 +08)" skipped: maximum number of running instances reached (1)
Job "run.<locals>.<lambda> (trigger: cron[minute='*/1', second='5'], next run at: 2017-11-23 13:12:05 +08)" raised an exception
Traceback (most recent call last):
  File "/Library/Frameworks/Python.framework/Versions/3.6/lib/python3.6/site-packages/apscheduler/executors/base.py", line 125, in run_job
    retval = job.func(*job.args, **job.kwargs)
  File "/Users/tianyangzhao/PycharmProjects/universal_ems/local_ems.py", line 106, in <lambda>
    session_lems_middle),
  File "/Users/tianyangzhao/PycharmProjects/universal_ems/economic_dispatch/main.py", line 125, in middle_term_operation_lems
    dynamic_model = information_formulation_extraction_dynamic.info_formulation(local_models, Target_time, "ED")
  File "/Users/tianyangzhao/PycharmProjects/universal_ems/data_management/information_management.py", line 238, in info_formulation
    ug_info.PG.extend([model["UG"]["COMMAND_PG"]])
  File "/Library/Frameworks/Python.framework/Versions/3.6/lib/python3.6/site-packages/google/protobuf/internal/containers.py", line 275, in extend
    new_values = [self._type_checker.CheckValue(elem) for elem in elem_seq_iter]
  File "/Library/Frameworks/Python.framework/Versions/3.6/lib/python3.6/site-packages/google/protobuf/internal/containers.py", line 275, in <listcomp>
    new_values = [self._type_checker.CheckValue(elem) for elem in elem_seq_iter]
  File "/Library/Frameworks/Python.framework/Versions/3.6/lib/python3.6/site-packages/google/protobuf/internal/type_checkers.py", line 133, in CheckValue
    raise TypeError(message)
TypeError: [3000, 3000, 1200, 2461, 2721, 3000, 3000, 3000, 3000, 2759, 1979, 2383] has type <class 'google.protobuf.internal.containers.RepeatedScalarFieldContainer'>, but expected one of: (<class 'int'>,)
Job "run.<locals>.<lambda> (trigger: cron[minute='*/1', second='5'], next run at: 2017-11-23 13:15:05 +08)" raised an exception
Traceback (most recent call last):
  File "/Library/Frameworks/Python.framework/Versions/3.6/lib/python3.6/site-packages/apscheduler/executors/base.py", line 125, in run_job
    retval = job.func(*job.args, **job.kwargs)
  File "/Users/tianyangzhao/PycharmProjects/universal_ems/local_ems.py", line 106, in <lambda>
    session_lems_middle),
  File "/Users/tianyangzhao/PycharmProjects/universal_ems/economic_dispatch/main.py", line 125, in middle_term_operation_lems
    dynamic_model = information_formulation_extraction_dynamic.info_formulation(local_models, Target_time, "ED")
  File "/Users/tianyangzhao/PycharmProjects/universal_ems/data_management/information_management.py", line 238, in info_formulation
    ug_info.PG.extend([model["UG"]["COMMAND_PG"]])
  File "/Library/Frameworks/Python.framework/Versions/3.6/lib/python3.6/site-packages/google/protobuf/internal/containers.py", line 275, in extend
    new_values = [self._type_checker.CheckValue(elem) for elem in elem_seq_iter]
  File "/Library/Frameworks/Python.framework/Versions/3.6/lib/python3.6/site-packages/google/protobuf/internal/containers.py", line 275, in <listcomp>
    new_values = [self._type_checker.CheckValue(elem) for elem in elem_seq_iter]
  File "/Library/Frameworks/Python.framework/Versions/3.6/lib/python3.6/site-packages/google/protobuf/internal/type_checkers.py", line 133, in CheckValue
    raise TypeError(message)
TypeError: [3000, 3000, 3000, 3000, 1021, 3000, 3000, 781, 3000, 3000, 3000, 3000] has type <class 'google.protobuf.internal.containers.RepeatedScalarFieldContainer'>, but expected one of: (<class 'int'>,)
Execution of job "short_term_operation.short_term_operation_uems (trigger: cron[minute='0-59', second='1'], next run at: 2017-11-23 14:16:01 +08)" skipped: maximum number of running instances reached (1)
Job "run.<locals>.<lambda> (trigger: cron[minute='0-59', second='1'], next run at: 2017-11-23 14:28:01 +08)" raised an exception
Traceback (most recent call last):
  File "/Library/Frameworks/Python.framework/Versions/3.6/lib/python3.6/site-packages/apscheduler/executors/base.py", line 125, in run_job
    retval = job.func(*job.args, **job.kwargs)
  File "/Users/tianyangzhao/PycharmProjects/universal_ems/local_ems.py", line 100, in <lambda>
    session_lems_short),
  File "/Users/tianyangzhao/PycharmProjects/universal_ems/optimal_power_flow/main.py", line 117, in short_term_operation_lems
    dynamic_model = information_formulation_extraction.info_formulation(local_models, Target_time)
  File "/Users/tianyangzhao/PycharmProjects/universal_ems/data_management/information_management.py", line 57, in info_formulation
    ug_info.PG = model["UG"]["COMMAND_PG"]
  File "/Library/Frameworks/Python.framework/Versions/3.6/lib/python3.6/site-packages/google/protobuf/internal/python_message.py", line 662, in field_setter
    new_value = type_checker.CheckValue(new_value)
  File "/Library/Frameworks/Python.framework/Versions/3.6/lib/python3.6/site-packages/google/protobuf/internal/type_checkers.py", line 133, in CheckValue
    raise TypeError(message)
TypeError: [1181, 877, 0, 0, 706, 0, 0, 1421, 1560, 1507, 0, 615] has type <class 'list'>, but expected one of: (<class 'int'>,)
Job "run.<locals>.<lambda> (trigger: cron[minute='0-59', second='1'], next run at: 2017-11-23 14:30:01 +08)" raised an exception
Traceback (most recent call last):
  File "/Library/Frameworks/Python.framework/Versions/3.6/lib/python3.6/site-packages/apscheduler/executors/base.py", line 125, in run_job
    retval = job.func(*job.args, **job.kwargs)
  File "/Users/tianyangzhao/PycharmProjects/universal_ems/local_ems.py", line 100, in <lambda>
    session_lems_short),
  File "/Users/tianyangzhao/PycharmProjects/universal_ems/optimal_power_flow/main.py", line 117, in short_term_operation_lems
    dynamic_model = information_formulation_extraction.info_formulation(local_models, Target_time)
  File "/Users/tianyangzhao/PycharmProjects/universal_ems/data_management/information_management.py", line 57, in info_formulation
    ug_info.PG = model["UG"]["COMMAND_PG"]
  File "/Library/Frameworks/Python.framework/Versions/3.6/lib/python3.6/site-packages/google/protobuf/internal/python_message.py", line 662, in field_setter
    new_value = type_checker.CheckValue(new_value)
  File "/Library/Frameworks/Python.framework/Versions/3.6/lib/python3.6/site-packages/google/protobuf/internal/type_checkers.py", line 133, in CheckValue
    raise TypeError(message)
TypeError: [758, 0, 0, 0, 456, 768, 268, 0, 1556, 571, 0, 994] has type <class 'list'>, but expected one of: (<class 'int'>,)
Execution of job "short_term_operation.short_term_operation_uems (trigger: cron[minute='0-59', second='1'], next run at: 2017-11-23 14:30:01 +08)" skipped: maximum number of running instances reached (1)
Job "run.<locals>.<lambda> (trigger: cron[minute='0-59', second='1'], next run at: 2017-11-23 14:31:01 +08)" raised an exception
Traceback (most recent call last):
  File "/Library/Frameworks/Python.framework/Versions/3.6/lib/python3.6/site-packages/apscheduler/executors/base.py", line 125, in run_job
    retval = job.func(*job.args, **job.kwargs)
  File "/Users/tianyangzhao/PycharmProjects/universal_ems/local_ems.py", line 100, in <lambda>
    session_lems_short),
  File "/Users/tianyangzhao/PycharmProjects/universal_ems/optimal_power_flow/main.py", line 117, in short_term_operation_lems
    dynamic_model = information_formulation_extraction.info_formulation(local_models, Target_time)
  File "/Users/tianyangzhao/PycharmProjects/universal_ems/data_management/information_management.py", line 57, in info_formulation
    ug_info.PG = model["UG"]["COMMAND_PG"]
  File "/Library/Frameworks/Python.framework/Versions/3.6/lib/python3.6/site-packages/google/protobuf/internal/python_message.py", line 662, in field_setter
    new_value = type_checker.CheckValue(new_value)
  File "/Library/Frameworks/Python.framework/Versions/3.6/lib/python3.6/site-packages/google/protobuf/internal/type_checkers.py", line 133, in CheckValue
    raise TypeError(message)
TypeError: [758, 0, 0, 0, 456, 768, 268, 0, 1556, 571, 0, 994] has type <class 'list'>, but expected one of: (<class 'int'>,)
Execution of job "short_term_operation.short_term_operation_uems (trigger: cron[minute='0-59', second='1'], next run at: 2017-11-23 14:31:01 +08)" skipped: maximum number of running instances reached (1)
Job "run.<locals>.<lambda> (trigger: cron[minute='0-59', second='1'], next run at: 2017-11-23 14:32:01 +08)" raised an exception
Traceback (most recent call last):
  File "/Library/Frameworks/Python.framework/Versions/3.6/lib/python3.6/site-packages/apscheduler/executors/base.py", line 125, in run_job
    retval = job.func(*job.args, **job.kwargs)
  File "/Users/tianyangzhao/PycharmProjects/universal_ems/local_ems.py", line 100, in <lambda>
    session_lems_short),
  File "/Users/tianyangzhao/PycharmProjects/universal_ems/optimal_power_flow/main.py", line 117, in short_term_operation_lems
    dynamic_model = information_formulation_extraction.info_formulation(local_models, Target_time)
  File "/Users/tianyangzhao/PycharmProjects/universal_ems/data_management/information_management.py", line 57, in info_formulation
    ug_info.PG = model["UG"]["COMMAND_PG"]
  File "/Library/Frameworks/Python.framework/Versions/3.6/lib/python3.6/site-packages/google/protobuf/internal/python_message.py", line 662, in field_setter
    new_value = type_checker.CheckValue(new_value)
  File "/Library/Frameworks/Python.framework/Versions/3.6/lib/python3.6/site-packages/google/protobuf/internal/type_checkers.py", line 133, in CheckValue
    raise TypeError(message)
TypeError: [842, 1418, 1094, 427, 364, 804, 1111, 0, 538, 0, 438, 0] has type <class 'list'>, but expected one of: (<class 'int'>,)
Execution of job "short_term_operation.short_term_operation_uems (trigger: cron[minute='0-59', second='1'], next run at: 2017-11-23 14:32:01 +08)" skipped: maximum number of running instances reached (1)
Job "run.<locals>.<lambda> (trigger: cron[minute='0-59', second='1'], next run at: 2017-11-23 14:33:01 +08)" raised an exception
Traceback (most recent call last):
  File "/Library/Frameworks/Python.framework/Versions/3.6/lib/python3.6/site-packages/apscheduler/executors/base.py", line 125, in run_job
    retval = job.func(*job.args, **job.kwargs)
  File "/Users/tianyangzhao/PycharmProjects/universal_ems/local_ems.py", line 100, in <lambda>
    session_lems_short),
  File "/Users/tianyangzhao/PycharmProjects/universal_ems/optimal_power_flow/main.py", line 117, in short_term_operation_lems
    dynamic_model = information_formulation_extraction.info_formulation(local_models, Target_time)
  File "/Users/tianyangzhao/PycharmProjects/universal_ems/data_management/information_management.py", line 57, in info_formulation
    ug_info.PG = model["UG"]["COMMAND_PG"]
  File "/Library/Frameworks/Python.framework/Versions/3.6/lib/python3.6/site-packages/google/protobuf/internal/python_message.py", line 662, in field_setter
    new_value = type_checker.CheckValue(new_value)
  File "/Library/Frameworks/Python.framework/Versions/3.6/lib/python3.6/site-packages/google/protobuf/internal/type_checkers.py", line 133, in CheckValue
    raise TypeError(message)
TypeError: [842, 1418, 1094, 427, 364, 804, 1111, 0, 538, 0, 438, 0] has type <class 'list'>, but expected one of: (<class 'int'>,)
Execution of job "short_term_operation.short_term_operation_uems (trigger: cron[minute='0-59', second='1'], next run at: 2017-11-23 14:33:01 +08)" skipped: maximum number of running instances reached (1)
Job "run.<locals>.<lambda> (trigger: cron[minute='0-59', second='1'], next run at: 2017-11-23 14:34:01 +08)" raised an exception
Traceback (most recent call last):
  File "/Library/Frameworks/Python.framework/Versions/3.6/lib/python3.6/site-packages/apscheduler/executors/base.py", line 125, in run_job
    retval = job.func(*job.args, **job.kwargs)
  File "/Users/tianyangzhao/PycharmProjects/universal_ems/local_ems.py", line 100, in <lambda>
    session_lems_short),
  File "/Users/tianyangzhao/PycharmProjects/universal_ems/optimal_power_flow/main.py", line 117, in short_term_operation_lems
    dynamic_model = information_formulation_extraction.info_formulation(local_models, Target_time)
  File "/Users/tianyangzhao/PycharmProjects/universal_ems/data_management/information_management.py", line 57, in info_formulation
    ug_info.PG = model["UG"]["COMMAND_PG"]
  File "/Library/Frameworks/Python.framework/Versions/3.6/lib/python3.6/site-packages/google/protobuf/internal/python_message.py", line 662, in field_setter
    new_value = type_checker.CheckValue(new_value)
  File "/Library/Frameworks/Python.framework/Versions/3.6/lib/python3.6/site-packages/google/protobuf/internal/type_checkers.py", line 133, in CheckValue
    raise TypeError(message)
TypeError: [0, 0, 823, 0, 0, 0, 0, 464, 1107, 1148, 921, 1176] has type <class 'list'>, but expected one of: (<class 'int'>,)
Execution of job "short_term_operation.short_term_operation_uems (trigger: cron[minute='0-59', second='1'], next run at: 2017-11-23 14:34:01 +08)" skipped: maximum number of running instances reached (1)
Job "run.<locals>.<lambda> (trigger: cron[minute='0-59', second='1'], next run at: 2017-11-23 14:35:01 +08)" raised an exception
Traceback (most recent call last):
  File "/Library/Frameworks/Python.framework/Versions/3.6/lib/python3.6/site-packages/apscheduler/executors/base.py", line 125, in run_job
    retval = job.func(*job.args, **job.kwargs)
  File "/Users/tianyangzhao/PycharmProjects/universal_ems/local_ems.py", line 100, in <lambda>
    session_lems_short),
  File "/Users/tianyangzhao/PycharmProjects/universal_ems/optimal_power_flow/main.py", line 117, in short_term_operation_lems
    dynamic_model = information_formulation_extraction.info_formulation(local_models, Target_time)
  File "/Users/tianyangzhao/PycharmProjects/universal_ems/data_management/information_management.py", line 57, in info_formulation
    ug_info.PG = model["UG"]["COMMAND_PG"]
  File "/Library/Frameworks/Python.framework/Versions/3.6/lib/python3.6/site-packages/google/protobuf/internal/python_message.py", line 662, in field_setter
    new_value = type_checker.CheckValue(new_value)
  File "/Library/Frameworks/Python.framework/Versions/3.6/lib/python3.6/site-packages/google/protobuf/internal/type_checkers.py", line 133, in CheckValue
    raise TypeError(message)
TypeError: [0, 0, 823, 0, 0, 0, 0, 464, 1107, 1148, 921, 1176] has type <class 'list'>, but expected one of: (<class 'int'>,)
Execution of job "short_term_operation.short_term_operation_uems (trigger: cron[minute='0-59', second='1'], next run at: 2017-11-23 14:35:01 +08)" skipped: maximum number of running instances reached (1)
Job "run.<locals>.<lambda> (trigger: cron[minute='0-59', second='1'], next run at: 2017-11-23 14:36:01 +08)" raised an exception
Traceback (most recent call last):
  File "/Library/Frameworks/Python.framework/Versions/3.6/lib/python3.6/site-packages/apscheduler/executors/base.py", line 125, in run_job
    retval = job.func(*job.args, **job.kwargs)
  File "/Users/tianyangzhao/PycharmProjects/universal_ems/local_ems.py", line 100, in <lambda>
    session_lems_short),
  File "/Users/tianyangzhao/PycharmProjects/universal_ems/optimal_power_flow/main.py", line 117, in short_term_operation_lems
    dynamic_model = information_formulation_extraction.info_formulation(local_models, Target_time)
  File "/Users/tianyangzhao/PycharmProjects/universal_ems/data_management/information_management.py", line 57, in info_formulation
    ug_info.PG = model["UG"]["COMMAND_PG"]
  File "/Library/Frameworks/Python.framework/Versions/3.6/lib/python3.6/site-packages/google/protobuf/internal/python_message.py", line 662, in field_setter
    new_value = type_checker.CheckValue(new_value)
  File "/Library/Frameworks/Python.framework/Versions/3.6/lib/python3.6/site-packages/google/protobuf/internal/type_checkers.py", line 133, in CheckValue
    raise TypeError(message)
TypeError: [558, 1255, 402, 1170, 990, 986, 1333, 1050, 0, 0, 357, 0] has type <class 'list'>, but expected one of: (<class 'int'>,)
Execution of job "short_term_operation.short_term_operation_uems (trigger: cron[minute='0-59', second='1'], next run at: 2017-11-23 14:36:01 +08)" skipped: maximum number of running instances reached (1)
Job "run.<locals>.<lambda> (trigger: cron[minute='0-59', second='1'], next run at: 2017-11-23 14:37:01 +08)" raised an exception
Traceback (most recent call last):
  File "/Library/Frameworks/Python.framework/Versions/3.6/lib/python3.6/site-packages/apscheduler/executors/base.py", line 125, in run_job
    retval = job.func(*job.args, **job.kwargs)
  File "/Users/tianyangzhao/PycharmProjects/universal_ems/local_ems.py", line 100, in <lambda>
    session_lems_short),
  File "/Users/tianyangzhao/PycharmProjects/universal_ems/optimal_power_flow/main.py", line 117, in short_term_operation_lems
    dynamic_model = information_formulation_extraction.info_formulation(local_models, Target_time)
  File "/Users/tianyangzhao/PycharmProjects/universal_ems/data_management/information_management.py", line 57, in info_formulation
    ug_info.PG = model["UG"]["COMMAND_PG"]
  File "/Library/Frameworks/Python.framework/Versions/3.6/lib/python3.6/site-packages/google/protobuf/internal/python_message.py", line 662, in field_setter
    new_value = type_checker.CheckValue(new_value)
  File "/Library/Frameworks/Python.framework/Versions/3.6/lib/python3.6/site-packages/google/protobuf/internal/type_checkers.py", line 133, in CheckValue
    raise TypeError(message)
TypeError: [558, 1255, 402, 1170, 990, 986, 1333, 1050, 0, 0, 357, 0] has type <class 'list'>, but expected one of: (<class 'int'>,)
Job "run.<locals>.<lambda> (trigger: cron[minute='0-59', second='1'], next run at: 2017-11-23 14:38:01 +08)" raised an exception
Traceback (most recent call last):
  File "/Library/Frameworks/Python.framework/Versions/3.6/lib/python3.6/site-packages/apscheduler/executors/base.py", line 125, in run_job
    retval = job.func(*job.args, **job.kwargs)
  File "/Users/tianyangzhao/PycharmProjects/universal_ems/local_ems.py", line 100, in <lambda>
    session_lems_short),
  File "/Users/tianyangzhao/PycharmProjects/universal_ems/optimal_power_flow/main.py", line 117, in short_term_operation_lems
    dynamic_model = information_formulation_extraction.info_formulation(local_models, Target_time)
  File "/Users/tianyangzhao/PycharmProjects/universal_ems/data_management/information_management.py", line 57, in info_formulation
    ug_info.PG = model["UG"]["COMMAND_PG"]
  File "/Library/Frameworks/Python.framework/Versions/3.6/lib/python3.6/site-packages/google/protobuf/internal/python_message.py", line 662, in field_setter
    new_value = type_checker.CheckValue(new_value)
  File "/Library/Frameworks/Python.framework/Versions/3.6/lib/python3.6/site-packages/google/protobuf/internal/type_checkers.py", line 133, in CheckValue
    raise TypeError(message)
TypeError: [1158, 3000, 793, 2090, 3000, 878, 3000, 246, 3000, 2680, 2877, 3000] has type <class 'list'>, but expected one of: (<class 'int'>,)
Execution of job "short_term_operation.short_term_operation_uems (trigger: cron[minute='0-59', second='1'], next run at: 2017-11-23 14:38:01 +08)" skipped: maximum number of running instances reached (1)
Job "run.<locals>.<lambda> (trigger: cron[minute='0-59', second='1'], next run at: 2017-11-23 14:39:01 +08)" raised an exception
Traceback (most recent call last):
  File "/Library/Frameworks/Python.framework/Versions/3.6/lib/python3.6/site-packages/apscheduler/executors/base.py", line 125, in run_job
    retval = job.func(*job.args, **job.kwargs)
  File "/Users/tianyangzhao/PycharmProjects/universal_ems/local_ems.py", line 100, in <lambda>
    session_lems_short),
  File "/Users/tianyangzhao/PycharmProjects/universal_ems/optimal_power_flow/main.py", line 117, in short_term_operation_lems
    dynamic_model = information_formulation_extraction.info_formulation(local_models, Target_time)
  File "/Users/tianyangzhao/PycharmProjects/universal_ems/data_management/information_management.py", line 57, in info_formulation
    ug_info.PG = model["UG"]["COMMAND_PG"]
  File "/Library/Frameworks/Python.framework/Versions/3.6/lib/python3.6/site-packages/google/protobuf/internal/python_message.py", line 662, in field_setter
    new_value = type_checker.CheckValue(new_value)
  File "/Library/Frameworks/Python.framework/Versions/3.6/lib/python3.6/site-packages/google/protobuf/internal/type_checkers.py", line 133, in CheckValue
    raise TypeError(message)
TypeError: [1158, 3000, 793, 2090, 3000, 878, 3000, 246, 3000, 2680, 2877, 3000] has type <class 'list'>, but expected one of: (<class 'int'>,)
Job "long_term_operation.long_term_operation_uems (trigger: cron[minute='*/2', second='30'], next run at: 2017-11-23 15:06:30 +08)" raised an exception
Traceback (most recent call last):
  File "/Library/Frameworks/Python.framework/Versions/3.6/lib/python3.6/site-packages/apscheduler/executors/base.py", line 125, in run_job
    retval = job.func(*job.args, **job.kwargs)
  File "/Users/tianyangzhao/PycharmProjects/universal_ems/unit_commitment/main.py", line 59, in long_term_operation_uems
    "Feasible")
  File "/Users/tianyangzhao/PycharmProjects/universal_ems/unit_commitment/problem_formulation.py", line 451, in problem_formulation_universal
    beq_compact[neq:2 * neq] = universal_model_mathematical["beq"]
ValueError: setting an array element with a sequence.
Execution of job "run.<locals>.<lambda> (trigger: cron[minute='*/2', second='30'], next run at: 2017-11-23 15:06:30 +08)" skipped: maximum number of running instances reached (1)
Job "long_term_operation.long_term_operation_uems (trigger: cron[minute='*/2', second='30'], next run at: 2017-11-23 15:08:30 +08)" raised an exception
Traceback (most recent call last):
  File "/Library/Frameworks/Python.framework/Versions/3.6/lib/python3.6/site-packages/apscheduler/executors/base.py", line 125, in run_job
    retval = job.func(*job.args, **job.kwargs)
  File "/Users/tianyangzhao/PycharmProjects/universal_ems/unit_commitment/main.py", line 59, in long_term_operation_uems
    "Feasible")
  File "/Users/tianyangzhao/PycharmProjects/universal_ems/unit_commitment/problem_formulation.py", line 451, in problem_formulation_universal
    beq_compact[neq:2 * neq] = universal_model_mathematical["beq"]
ValueError: setting an array element with a sequence.
Job "long_term_operation.long_term_operation_uems (trigger: cron[minute='*/1', second='30'], next run at: 2017-11-23 15:10:30 +08)" raised an exception
Traceback (most recent call last):
  File "/Library/Frameworks/Python.framework/Versions/3.6/lib/python3.6/site-packages/apscheduler/executors/base.py", line 125, in run_job
    retval = job.func(*job.args, **job.kwargs)
  File "/Users/tianyangzhao/PycharmProjects/universal_ems/unit_commitment/main.py", line 59, in long_term_operation_uems
    "Feasible")
  File "/Users/tianyangzhao/PycharmProjects/universal_ems/unit_commitment/problem_formulation.py", line 451, in problem_formulation_universal
    beq_compact[neq:2 * neq] = universal_model_mathematical["beq"]
ValueError: setting an array element with a sequence.
Execution of job "run.<locals>.<lambda> (trigger: cron[minute='*/1', second='30'], next run at: 2017-11-23 15:10:30 +08)" skipped: maximum number of running instances reached (1)
Job "long_term_operation.long_term_operation_uems (trigger: cron[minute='*/1', second='30'], next run at: 2017-11-23 15:11:30 +08)" raised an exception
Traceback (most recent call last):
  File "/Library/Frameworks/Python.framework/Versions/3.6/lib/python3.6/site-packages/apscheduler/executors/base.py", line 125, in run_job
    retval = job.func(*job.args, **job.kwargs)
  File "/Users/tianyangzhao/PycharmProjects/universal_ems/unit_commitment/main.py", line 59, in long_term_operation_uems
    "Feasible")
  File "/Users/tianyangzhao/PycharmProjects/universal_ems/unit_commitment/problem_formulation.py", line 451, in problem_formulation_universal
    beq_compact[neq:2 * neq] = universal_model_mathematical["beq"]
ValueError: setting an array element with a sequence.
Execution of job "run.<locals>.<lambda> (trigger: cron[minute='*/1', second='30'], next run at: 2017-11-23 15:11:30 +08)" skipped: maximum number of running instances reached (1)
Job "long_term_operation.long_term_operation_uems (trigger: cron[minute='*/1', second='30'], next run at: 2017-11-23 15:12:30 +08)" raised an exception
Traceback (most recent call last):
  File "/Library/Frameworks/Python.framework/Versions/3.6/lib/python3.6/site-packages/apscheduler/executors/base.py", line 125, in run_job
    retval = job.func(*job.args, **job.kwargs)
  File "/Users/tianyangzhao/PycharmProjects/universal_ems/unit_commitment/main.py", line 59, in long_term_operation_uems
    "Feasible")
  File "/Users/tianyangzhao/PycharmProjects/universal_ems/unit_commitment/problem_formulation.py", line 451, in problem_formulation_universal
    beq_compact[neq:2 * neq] = universal_model_mathematical["beq"]
ValueError: setting an array element with a sequence.
Execution of job "run.<locals>.<lambda> (trigger: cron[minute='*/1', second='30'], next run at: 2017-11-23 22:33:30 +08)" skipped: maximum number of running instances reached (1)
Execution of job "run.<locals>.<lambda> (trigger: cron[minute='*/2', second='5'], next run at: 2017-11-23 22:34:05 +08)" skipped: maximum number of running instances reached (1)
Execution of job "run.<locals>.<lambda> (trigger: cron[minute='*/1', second='30'], next run at: 2017-11-23 22:34:30 +08)" skipped: maximum number of running instances reached (1)
Execution of job "run.<locals>.<lambda> (trigger: cron[minute='0-59', second='1'], next run at: 2017-11-23 22:41:01 +08)" skipped: maximum number of running instances reached (1)
Run time of job "run.<locals>.<lambda> (trigger: cron[minute='0-59', second='1'], next run at: 2017-11-24 09:46:01 +08)" was missed by 0:00:02.900239
Run time of job "short_term_operation.short_term_operation_uems (trigger: cron[minute='0-59', second='1'], next run at: 2017-11-24 09:46:01 +08)" was missed by 0:00:02.900265
Run time of job "short_term_operation.short_term_operation_uems (trigger: cron[minute='0-59', second='1'], next run at: 2017-11-24 11:00:01 +08)" was missed by 0:00:36.884298
Run time of job "run.<locals>.<lambda> (trigger: cron[minute='0-59', second='1'], next run at: 2017-11-24 11:00:01 +08)" was missed by 0:00:36.884296
